2024-10-21 15:55:10,913 INFO    StreamThr :1475475 [internal.py:wandb_internal():85] W&B internal server running at pid: 1475475, started at: 2024-10-21 15:55:10.912738
2024-10-21 15:55:10,916 DEBUG   HandlerThread:1475475 [handler.py:handle_request():158] handle_request: status
2024-10-21 15:55:10,917 INFO    WriterThread:1475475 [datastore.py:open_for_write():87] open: /home/zwling/code/OOD-Libraries/wandb/run-20241021_155510-78bh6aux/run-78bh6aux.wandb
2024-10-21 15:55:10,918 DEBUG   SenderThread:1475475 [sender.py:send():391] send: header
2024-10-21 15:55:10,920 DEBUG   SenderThread:1475475 [sender.py:send():391] send: run
2024-10-21 15:55:15,922 DEBUG   HandlerThread:1475475 [handler.py:handle_request():158] handle_request: keepalive
2024-10-21 15:55:20,923 DEBUG   HandlerThread:1475475 [handler.py:handle_request():158] handle_request: keepalive
2024-10-21 15:55:25,925 DEBUG   HandlerThread:1475475 [handler.py:handle_request():158] handle_request: keepalive
2024-10-21 15:55:30,926 DEBUG   HandlerThread:1475475 [handler.py:handle_request():158] handle_request: keepalive
2024-10-21 15:55:35,927 DEBUG   HandlerThread:1475475 [handler.py:handle_request():158] handle_request: keepalive
2024-10-21 15:55:40,928 DEBUG   HandlerThread:1475475 [handler.py:handle_request():158] handle_request: keepalive
2024-10-21 15:55:45,930 DEBUG   HandlerThread:1475475 [handler.py:handle_request():158] handle_request: keepalive
2024-10-21 15:55:50,932 DEBUG   HandlerThread:1475475 [handler.py:handle_request():158] handle_request: keepalive
2024-10-21 15:55:55,934 DEBUG   HandlerThread:1475475 [handler.py:handle_request():158] handle_request: keepalive
2024-10-21 15:56:00,936 DEBUG   HandlerThread:1475475 [handler.py:handle_request():158] handle_request: keepalive
2024-10-21 15:56:05,938 DEBUG   HandlerThread:1475475 [handler.py:handle_request():158] handle_request: keepalive
2024-10-21 15:56:10,940 DEBUG   HandlerThread:1475475 [handler.py:handle_request():158] handle_request: keepalive
2024-10-21 15:56:14,400 INFO    SenderThread:1475475 [retry.py:__call__():172] Retry attempt failed:
Traceback (most recent call last):
  File "/home/zwling/.conda/envs/lzw/lib/python3.10/site-packages/urllib3/connection.py", line 196, in _new_conn
    sock = connection.create_connection(
  File "/home/zwling/.conda/envs/lzw/lib/python3.10/site-packages/urllib3/util/connection.py", line 85, in create_connection
    raise err
  File "/home/zwling/.conda/envs/lzw/lib/python3.10/site-packages/urllib3/util/connection.py", line 73, in create_connection
    sock.connect(sa)
TimeoutError: timed out

The above exception was the direct cause of the following exception:

Traceback (most recent call last):
  File "/home/zwling/.conda/envs/lzw/lib/python3.10/site-packages/urllib3/connectionpool.py", line 789, in urlopen
    response = self._make_request(
  File "/home/zwling/.conda/envs/lzw/lib/python3.10/site-packages/urllib3/connectionpool.py", line 490, in _make_request
    raise new_e
  File "/home/zwling/.conda/envs/lzw/lib/python3.10/site-packages/urllib3/connectionpool.py", line 466, in _make_request
    self._validate_conn(conn)
  File "/home/zwling/.conda/envs/lzw/lib/python3.10/site-packages/urllib3/connectionpool.py", line 1095, in _validate_conn
    conn.connect()
  File "/home/zwling/.conda/envs/lzw/lib/python3.10/site-packages/urllib3/connection.py", line 615, in connect
    self.sock = sock = self._new_conn()
  File "/home/zwling/.conda/envs/lzw/lib/python3.10/site-packages/urllib3/connection.py", line 205, in _new_conn
    raise ConnectTimeoutError(
urllib3.exceptions.ConnectTimeoutError: (<urllib3.connection.HTTPSConnection object at 0x7fe149106e00>, 'Connection to api.wandb.ai timed out. (connect timeout=20)')

The above exception was the direct cause of the following exception:

Traceback (most recent call last):
  File "/home/zwling/.conda/envs/lzw/lib/python3.10/site-packages/requests/adapters.py", line 667, in send
    resp = conn.urlopen(
  File "/home/zwling/.conda/envs/lzw/lib/python3.10/site-packages/urllib3/connectionpool.py", line 843, in urlopen
    retries = retries.increment(
  File "/home/zwling/.conda/envs/lzw/lib/python3.10/site-packages/urllib3/util/retry.py", line 519, in increment
    raise MaxRetryError(_pool, url, reason) from reason  # type: ignore[arg-type]
urllib3.exceptions.MaxRetryError: HTTPSConnectionPool(host='api.wandb.ai', port=443): Max retries exceeded with url: /graphql (Caused by ConnectTimeoutError(<urllib3.connection.HTTPSConnection object at 0x7fe149106e00>, 'Connection to api.wandb.ai timed out. (connect timeout=20)'))

During handling of the above exception, another exception occurred:

Traceback (most recent call last):
  File "/home/zwling/.conda/envs/lzw/lib/python3.10/site-packages/wandb/sdk/lib/retry.py", line 131, in __call__
    result = self._call_fn(*args, **kwargs)
  File "/home/zwling/.conda/envs/lzw/lib/python3.10/site-packages/wandb/sdk/internal/internal_api.py", line 345, in execute
    return self.client.execute(*args, **kwargs)  # type: ignore
  File "/home/zwling/.conda/envs/lzw/lib/python3.10/site-packages/wandb/vendor/gql-0.2.0/wandb_gql/client.py", line 52, in execute
    result = self._get_result(document, *args, **kwargs)
  File "/home/zwling/.conda/envs/lzw/lib/python3.10/site-packages/wandb/vendor/gql-0.2.0/wandb_gql/client.py", line 60, in _get_result
    return self.transport.execute(document, *args, **kwargs)
  File "/home/zwling/.conda/envs/lzw/lib/python3.10/site-packages/wandb/sdk/lib/gql_request.py", line 58, in execute
    request = self.session.post(self.url, **post_args)
  File "/home/zwling/.conda/envs/lzw/lib/python3.10/site-packages/requests/sessions.py", line 637, in post
    return self.request("POST", url, data=data, json=json, **kwargs)
  File "/home/zwling/.conda/envs/lzw/lib/python3.10/site-packages/requests/sessions.py", line 589, in request
    resp = self.send(prep, **send_kwargs)
  File "/home/zwling/.conda/envs/lzw/lib/python3.10/site-packages/requests/sessions.py", line 703, in send
    r = adapter.send(request, **kwargs)
  File "/home/zwling/.conda/envs/lzw/lib/python3.10/site-packages/requests/adapters.py", line 688, in send
    raise ConnectTimeout(e, request=request)
requests.exceptions.ConnectTimeout: HTTPSConnectionPool(host='api.wandb.ai', port=443): Max retries exceeded with url: /graphql (Caused by ConnectTimeoutError(<urllib3.connection.HTTPSConnection object at 0x7fe149106e00>, 'Connection to api.wandb.ai timed out. (connect timeout=20)'))
2024-10-21 15:56:15,941 DEBUG   HandlerThread:1475475 [handler.py:handle_request():158] handle_request: keepalive
2024-10-21 15:56:20,943 DEBUG   HandlerThread:1475475 [handler.py:handle_request():158] handle_request: keepalive
2024-10-21 15:56:21,008 INFO    SenderThread:1475475 [dir_watcher.py:__init__():211] watching files in: /home/zwling/code/OOD-Libraries/wandb/run-20241021_155510-78bh6aux/files
2024-10-21 15:56:21,009 INFO    SenderThread:1475475 [sender.py:_start_run_threads():1200] run started: 78bh6aux with start time 1729497310.91265
2024-10-21 15:56:21,009 DEBUG   HandlerThread:1475475 [handler.py:handle_request():158] handle_request: status_report
2024-10-21 15:56:21,021 DEBUG   HandlerThread:1475475 [handler.py:handle_request():158] handle_request: run_start
2024-10-21 15:56:21,075 DEBUG   HandlerThread:1475475 [system_info.py:__init__():26] System info init
2024-10-21 15:56:21,076 DEBUG   HandlerThread:1475475 [system_info.py:__init__():41] System info init done
2024-10-21 15:56:21,076 INFO    HandlerThread:1475475 [system_monitor.py:start():194] Starting system monitor
2024-10-21 15:56:21,076 INFO    SystemMonitor:1475475 [system_monitor.py:_start():158] Starting system asset monitoring threads
2024-10-21 15:56:21,077 INFO    HandlerThread:1475475 [system_monitor.py:probe():214] Collecting system info
2024-10-21 15:56:21,079 INFO    SystemMonitor:1475475 [interfaces.py:start():188] Started cpu monitoring
2024-10-21 15:56:21,079 INFO    SystemMonitor:1475475 [interfaces.py:start():188] Started disk monitoring
2024-10-21 15:56:21,081 INFO    SystemMonitor:1475475 [interfaces.py:start():188] Started gpu monitoring
2024-10-21 15:56:21,081 INFO    SystemMonitor:1475475 [interfaces.py:start():188] Started memory monitoring
2024-10-21 15:56:21,082 INFO    SystemMonitor:1475475 [interfaces.py:start():188] Started network monitoring
2024-10-21 15:56:21,163 DEBUG   HandlerThread:1475475 [system_info.py:probe():152] Probing system
2024-10-21 15:56:21,167 DEBUG   HandlerThread:1475475 [system_info.py:_probe_git():137] Probing git
2024-10-21 15:56:21,174 DEBUG   HandlerThread:1475475 [system_info.py:_probe_git():145] Probing git done
2024-10-21 15:56:21,174 DEBUG   HandlerThread:1475475 [system_info.py:probe():200] Probing system done
2024-10-21 15:56:21,174 DEBUG   HandlerThread:1475475 [system_monitor.py:probe():223] {'os': 'Linux-5.15.0-112-generic-x86_64-with-glibc2.35', 'python': '3.10.14', 'heartbeatAt': '2024-10-21T07:56:21.163328', 'startedAt': '2024-10-21T07:55:10.907104', 'docker': None, 'cuda': None, 'args': ('--gpu', '1'), 'state': 'running', 'program': '/home/zwling/code/OOD-Libraries/ood_eval.py', 'codePathLocal': 'ood_eval.py', 'codePath': 'ood_eval.py', 'git': {'remote': 'https://github.com/LingAndZero/OOD-Libraries.git', 'commit': '4e0e773582eb9065f0aba3e76dd5f76fc87ce9ca'}, 'email': 'zhiweiling1999@outlook.com', 'root': '/home/zwling/code/OOD-Libraries', 'host': 'red', 'username': 'zwling', 'executable': '/home/zwling/.conda/envs/lzw/bin/python', 'cpu_count': 96, 'cpu_count_logical': 192, 'cpu_freq': {'current': 1795.253046875, 'min': 1500.0, 'max': 2550.0}, 'cpu_freq_per_core': [{'current': 1500.0, 'min': 1500.0, 'max': 2550.0}, {'current': 1500.0, 'min': 1500.0, 'max': 2550.0}, {'current': 1500.0, 'min': 1500.0, 'max': 2550.0}, {'current': 1500.0, 'min': 1500.0, 'max': 2550.0}, {'current': 1500.0, 'min': 1500.0, 'max': 2550.0}, {'current': 1500.0, 'min': 1500.0, 'max': 2550.0}, {'current': 2550.0, 'min': 1500.0, 'max': 2550.0}, {'current': 1500.0, 'min': 1500.0, 'max': 2550.0}, {'current': 1500.0, 'min': 1500.0, 'max': 2550.0}, {'current': 1500.0, 'min': 1500.0, 'max': 2550.0}, {'current': 2550.0, 'min': 1500.0, 'max': 2550.0}, {'current': 1500.0, 'min': 1500.0, 'max': 2550.0}, {'current': 1500.0, 'min': 1500.0, 'max': 2550.0}, {'current': 2550.0, 'min': 1500.0, 'max': 2550.0}, {'current': 1500.0, 'min': 1500.0, 'max': 2550.0}, {'current': 1500.0, 'min': 1500.0, 'max': 2550.0}, {'current': 1500.0, 'min': 1500.0, 'max': 2550.0}, {'current': 2550.0, 'min': 1500.0, 'max': 2550.0}, {'current': 1500.0, 'min': 1500.0, 'max': 2550.0}, {'current': 1500.0, 'min': 1500.0, 'max': 2550.0}, {'current': 1500.0, 'min': 1500.0, 'max': 2550.0}, {'current': 1500.0, 'min': 1500.0, 'max': 2550.0}, {'current': 1500.0, 'min': 1500.0, 'max': 2550.0}, {'current': 1500.0, 'min': 1500.0, 'max': 2550.0}, {'current': 1500.0, 'min': 1500.0, 'max': 2550.0}, {'current': 1500.0, 'min': 1500.0, 'max': 2550.0}, {'current': 1500.0, 'min': 1500.0, 'max': 2550.0}, {'current': 1500.0, 'min': 1500.0, 'max': 2550.0}, {'current': 1500.0, 'min': 1500.0, 'max': 2550.0}, {'current': 1500.0, 'min': 1500.0, 'max': 2550.0}, {'current': 1500.0, 'min': 1500.0, 'max': 2550.0}, {'current': 1500.0, 'min': 1500.0, 'max': 2550.0}, {'current': 1500.0, 'min': 1500.0, 'max': 2550.0}, {'current': 1500.0, 'min': 1500.0, 'max': 2550.0}, {'current': 1500.0, 'min': 1500.0, 'max': 2550.0}, {'current': 1500.0, 'min': 1500.0, 'max': 2550.0}, {'current': 1500.0, 'min': 1500.0, 'max': 2550.0}, {'current': 1500.0, 'min': 1500.0, 'max': 2550.0}, {'current': 1500.0, 'min': 1500.0, 'max': 2550.0}, {'current': 1500.0, 'min': 1500.0, 'max': 2550.0}, {'current': 1500.0, 'min': 1500.0, 'max': 2550.0}, {'current': 1500.0, 'min': 1500.0, 'max': 2550.0}, {'current': 1500.0, 'min': 1500.0, 'max': 2550.0}, {'current': 2550.0, 'min': 1500.0, 'max': 2550.0}, {'current': 1500.0, 'min': 1500.0, 'max': 2550.0}, {'current': 2550.0, 'min': 1500.0, 'max': 2550.0}, {'current': 2550.0, 'min': 1500.0, 'max': 2550.0}, {'current': 1500.0, 'min': 1500.0, 'max': 2550.0}, {'current': 1500.0, 'min': 1500.0, 'max': 2550.0}, {'current': 1500.0, 'min': 1500.0, 'max': 2550.0}, {'current': 2550.0, 'min': 1500.0, 'max': 2550.0}, {'current': 1500.0, 'min': 1500.0, 'max': 2550.0}, {'current': 1500.0, 'min': 1500.0, 'max': 2550.0}, {'current': 2550.0, 'min': 1500.0, 'max': 2550.0}, {'current': 2550.0, 'min': 1500.0, 'max': 2550.0}, {'current': 1500.0, 'min': 1500.0, 'max': 2550.0}, {'current': 2550.0, 'min': 1500.0, 'max': 2550.0}, {'current': 2550.0, 'min': 1500.0, 'max': 2550.0}, {'current': 2550.0, 'min': 1500.0, 'max': 2550.0}, {'current': 2550.0, 'min': 1500.0, 'max': 2550.0}, {'current': 1500.0, 'min': 1500.0, 'max': 2550.0}, {'current': 2550.0, 'min': 1500.0, 'max': 2550.0}, {'current': 3617.339, 'min': 1500.0, 'max': 2550.0}, {'current': 1500.0, 'min': 1500.0, 'max': 2550.0}, {'current': 1500.0, 'min': 1500.0, 'max': 2550.0}, {'current': 1500.0, 'min': 1500.0, 'max': 2550.0}, {'current': 1500.0, 'min': 1500.0, 'max': 2550.0}, {'current': 1500.0, 'min': 1500.0, 'max': 2550.0}, {'current': 2550.0, 'min': 1500.0, 'max': 2550.0}, {'current': 1500.0, 'min': 1500.0, 'max': 2550.0}, {'current': 2550.0, 'min': 1500.0, 'max': 2550.0}, {'current': 1500.0, 'min': 1500.0, 'max': 2550.0}, {'current': 1500.0, 'min': 1500.0, 'max': 2550.0}, {'current': 1500.0, 'min': 1500.0, 'max': 2550.0}, {'current': 1500.0, 'min': 1500.0, 'max': 2550.0}, {'current': 2550.0, 'min': 1500.0, 'max': 2550.0}, {'current': 1500.0, 'min': 1500.0, 'max': 2550.0}, {'current': 1500.0, 'min': 1500.0, 'max': 2550.0}, {'current': 1500.0, 'min': 1500.0, 'max': 2550.0}, {'current': 1500.0, 'min': 1500.0, 'max': 2550.0}, {'current': 2550.0, 'min': 1500.0, 'max': 2550.0}, {'current': 1500.0, 'min': 1500.0, 'max': 2550.0}, {'current': 2550.0, 'min': 1500.0, 'max': 2550.0}, {'current': 2550.0, 'min': 1500.0, 'max': 2550.0}, {'current': 2550.0, 'min': 1500.0, 'max': 2550.0}, {'current': 1500.0, 'min': 1500.0, 'max': 2550.0}, {'current': 1500.0, 'min': 1500.0, 'max': 2550.0}, {'current': 2550.0, 'min': 1500.0, 'max': 2550.0}, {'current': 2550.0, 'min': 1500.0, 'max': 2550.0}, {'current': 2550.0, 'min': 1500.0, 'max': 2550.0}, {'current': 2550.0, 'min': 1500.0, 'max': 2550.0}, {'current': 2550.0, 'min': 1500.0, 'max': 2550.0}, {'current': 1500.0, 'min': 1500.0, 'max': 2550.0}, {'current': 1500.0, 'min': 1500.0, 'max': 2550.0}, {'current': 2550.0, 'min': 1500.0, 'max': 2550.0}, {'current': 1500.0, 'min': 1500.0, 'max': 2550.0}, {'current': 1500.0, 'min': 1500.0, 'max': 2550.0}, {'current': 1500.0, 'min': 1500.0, 'max': 2550.0}, {'current': 2550.0, 'min': 1500.0, 'max': 2550.0}, {'current': 1500.0, 'min': 1500.0, 'max': 2550.0}, {'current': 1500.0, 'min': 1500.0, 'max': 2550.0}, {'current': 1500.0, 'min': 1500.0, 'max': 2550.0}, {'current': 1500.0, 'min': 1500.0, 'max': 2550.0}, {'current': 1500.0, 'min': 1500.0, 'max': 2550.0}, {'current': 2550.0, 'min': 1500.0, 'max': 2550.0}, {'current': 1500.0, 'min': 1500.0, 'max': 2550.0}, {'current': 1500.0, 'min': 1500.0, 'max': 2550.0}, {'current': 1500.0, 'min': 1500.0, 'max': 2550.0}, {'current': 1500.0, 'min': 1500.0, 'max': 2550.0}, {'current': 1500.0, 'min': 1500.0, 'max': 2550.0}, {'current': 1500.0, 'min': 1500.0, 'max': 2550.0}, {'current': 1500.0, 'min': 1500.0, 'max': 2550.0}, {'current': 1500.0, 'min': 1500.0, 'max': 2550.0}, {'current': 1500.0, 'min': 1500.0, 'max': 2550.0}, {'current': 1500.0, 'min': 1500.0, 'max': 2550.0}, {'current': 1500.0, 'min': 1500.0, 'max': 2550.0}, {'current': 1500.0, 'min': 1500.0, 'max': 2550.0}, {'current': 1500.0, 'min': 1500.0, 'max': 2550.0}, {'current': 1500.0, 'min': 1500.0, 'max': 2550.0}, {'current': 1500.0, 'min': 1500.0, 'max': 2550.0}, {'current': 1500.0, 'min': 1500.0, 'max': 2550.0}, {'current': 1500.0, 'min': 1500.0, 'max': 2550.0}, {'current': 1500.0, 'min': 1500.0, 'max': 2550.0}, {'current': 2550.0, 'min': 1500.0, 'max': 2550.0}, {'current': 1500.0, 'min': 1500.0, 'max': 2550.0}, {'current': 1500.0, 'min': 1500.0, 'max': 2550.0}, {'current': 2550.0, 'min': 1500.0, 'max': 2550.0}, {'current': 1500.0, 'min': 1500.0, 'max': 2550.0}, {'current': 1500.0, 'min': 1500.0, 'max': 2550.0}, {'current': 2550.0, 'min': 1500.0, 'max': 2550.0}, {'current': 1500.0, 'min': 1500.0, 'max': 2550.0}, {'current': 1500.0, 'min': 1500.0, 'max': 2550.0}, {'current': 1500.0, 'min': 1500.0, 'max': 2550.0}, {'current': 1500.0, 'min': 1500.0, 'max': 2550.0}, {'current': 1500.0, 'min': 1500.0, 'max': 2550.0}, {'current': 1500.0, 'min': 1500.0, 'max': 2550.0}, {'current': 1500.0, 'min': 1500.0, 'max': 2550.0}, {'current': 1500.0, 'min': 1500.0, 'max': 2550.0}, {'current': 1500.0, 'min': 1500.0, 'max': 2550.0}, {'current': 1500.0, 'min': 1500.0, 'max': 2550.0}, {'current': 1500.0, 'min': 1500.0, 'max': 2550.0}, {'current': 1500.0, 'min': 1500.0, 'max': 2550.0}, {'current': 1500.0, 'min': 1500.0, 'max': 2550.0}, {'current': 1500.0, 'min': 1500.0, 'max': 2550.0}, {'current': 1500.0, 'min': 1500.0, 'max': 2550.0}, {'current': 2550.0, 'min': 1500.0, 'max': 2550.0}, {'current': 1500.0, 'min': 1500.0, 'max': 2550.0}, {'current': 1500.0, 'min': 1500.0, 'max': 2550.0}, {'current': 2550.0, 'min': 1500.0, 'max': 2550.0}, {'current': 2550.0, 'min': 1500.0, 'max': 2550.0}, {'current': 1500.0, 'min': 1500.0, 'max': 2550.0}, {'current': 2550.0, 'min': 1500.0, 'max': 2550.0}, {'current': 1500.0, 'min': 1500.0, 'max': 2550.0}, {'current': 1500.0, 'min': 1500.0, 'max': 2550.0}, {'current': 1500.0, 'min': 1500.0, 'max': 2550.0}, {'current': 2550.0, 'min': 1500.0, 'max': 2550.0}, {'current': 2550.0, 'min': 1500.0, 'max': 2550.0}, {'current': 1500.0, 'min': 1500.0, 'max': 2550.0}, {'current': 1500.0, 'min': 1500.0, 'max': 2550.0}, {'current': 1500.0, 'min': 1500.0, 'max': 2550.0}, {'current': 2550.0, 'min': 1500.0, 'max': 2550.0}, {'current': 1500.0, 'min': 1500.0, 'max': 2550.0}, {'current': 2550.0, 'min': 1500.0, 'max': 2550.0}, {'current': 1500.0, 'min': 1500.0, 'max': 2550.0}, {'current': 1500.0, 'min': 1500.0, 'max': 2550.0}, {'current': 1500.0, 'min': 1500.0, 'max': 2550.0}, {'current': 2550.0, 'min': 1500.0, 'max': 2550.0}, {'current': 2550.0, 'min': 1500.0, 'max': 2550.0}, {'current': 1500.0, 'min': 1500.0, 'max': 2550.0}, {'current': 1500.0, 'min': 1500.0, 'max': 2550.0}, {'current': 1500.0, 'min': 1500.0, 'max': 2550.0}, {'current': 1500.0, 'min': 1500.0, 'max': 2550.0}, {'current': 1500.0, 'min': 1500.0, 'max': 2550.0}, {'current': 1500.0, 'min': 1500.0, 'max': 2550.0}, {'current': 2550.0, 'min': 1500.0, 'max': 2550.0}, {'current': 1500.0, 'min': 1500.0, 'max': 2550.0}, {'current': 1500.0, 'min': 1500.0, 'max': 2550.0}, {'current': 2550.0, 'min': 1500.0, 'max': 2550.0}, {'current': 1500.0, 'min': 1500.0, 'max': 2550.0}, {'current': 1500.0, 'min': 1500.0, 'max': 2550.0}, {'current': 1500.0, 'min': 1500.0, 'max': 2550.0}, {'current': 2550.0, 'min': 1500.0, 'max': 2550.0}, {'current': 2550.0, 'min': 1500.0, 'max': 2550.0}, {'current': 1500.0, 'min': 1500.0, 'max': 2550.0}, {'current': 2550.0, 'min': 1500.0, 'max': 2550.0}, {'current': 2550.0, 'min': 1500.0, 'max': 2550.0}, {'current': 1500.0, 'min': 1500.0, 'max': 2550.0}, {'current': 2550.0, 'min': 1500.0, 'max': 2550.0}, {'current': 1500.0, 'min': 1500.0, 'max': 2550.0}, {'current': 2550.0, 'min': 1500.0, 'max': 2550.0}, {'current': 1500.0, 'min': 1500.0, 'max': 2550.0}, {'current': 2550.0, 'min': 1500.0, 'max': 2550.0}], 'disk': {'/': {'total': 589.5128479003906, 'used': 41.15840148925781}}, 'gpu': 'NVIDIA GeForce RTX 4090', 'gpu_count': 2, 'gpu_devices': [{'name': 'NVIDIA GeForce RTX 4090', 'memory_total': 25757220864}, {'name': 'NVIDIA GeForce RTX 4090', 'memory_total': 25757220864}], 'memory': {'total': 503.6810417175293}}
2024-10-21 15:56:21,175 INFO    HandlerThread:1475475 [system_monitor.py:probe():224] Finished collecting system info
2024-10-21 15:56:21,175 INFO    HandlerThread:1475475 [system_monitor.py:probe():227] Publishing system info
2024-10-21 15:56:21,175 DEBUG   HandlerThread:1475475 [system_info.py:_save_conda():209] Saving list of conda packages installed into the current environment
2024-10-21 15:56:22,010 INFO    Thread-12 :1475475 [dir_watcher.py:_on_file_created():271] file/dir created: /home/zwling/code/OOD-Libraries/wandb/run-20241021_155510-78bh6aux/files/conda-environment.yaml
2024-10-21 15:56:23,859 DEBUG   HandlerThread:1475475 [system_info.py:_save_conda():224] Saving conda packages done
2024-10-21 15:56:23,862 INFO    HandlerThread:1475475 [system_monitor.py:probe():229] Finished publishing system info
2024-10-21 15:56:23,875 DEBUG   SenderThread:1475475 [sender.py:send():391] send: files
2024-10-21 15:56:23,876 INFO    SenderThread:1475475 [sender.py:_save_file():1466] saving file wandb-metadata.json with policy now
2024-10-21 15:56:23,973 DEBUG   HandlerThread:1475475 [handler.py:handle_request():158] handle_request: python_packages
2024-10-21 15:56:23,973 DEBUG   SenderThread:1475475 [sender.py:send_request():418] send_request: python_packages
2024-10-21 15:56:23,974 DEBUG   HandlerThread:1475475 [handler.py:handle_request():158] handle_request: stop_status
2024-10-21 15:56:23,975 DEBUG   HandlerThread:1475475 [handler.py:handle_request():158] handle_request: internal_messages
2024-10-21 15:56:23,976 DEBUG   SenderThread:1475475 [sender.py:send_request():418] send_request: stop_status
2024-10-21 15:56:24,010 INFO    Thread-12 :1475475 [dir_watcher.py:_on_file_modified():288] file/dir modified: /home/zwling/code/OOD-Libraries/wandb/run-20241021_155510-78bh6aux/files/conda-environment.yaml
2024-10-21 15:56:24,010 INFO    Thread-12 :1475475 [dir_watcher.py:_on_file_created():271] file/dir created: /home/zwling/code/OOD-Libraries/wandb/run-20241021_155510-78bh6aux/files/requirements.txt
2024-10-21 15:56:24,011 INFO    Thread-12 :1475475 [dir_watcher.py:_on_file_created():271] file/dir created: /home/zwling/code/OOD-Libraries/wandb/run-20241021_155510-78bh6aux/files/wandb-metadata.json
2024-10-21 15:56:28,977 DEBUG   HandlerThread:1475475 [handler.py:handle_request():158] handle_request: keepalive
2024-10-21 15:56:33,975 DEBUG   HandlerThread:1475475 [handler.py:handle_request():158] handle_request: internal_messages
2024-10-21 15:56:38,977 DEBUG   HandlerThread:1475475 [handler.py:handle_request():158] handle_request: keepalive
2024-10-21 15:56:43,975 DEBUG   HandlerThread:1475475 [handler.py:handle_request():158] handle_request: internal_messages
2024-10-21 15:56:48,979 DEBUG   HandlerThread:1475475 [handler.py:handle_request():158] handle_request: keepalive
2024-10-21 15:56:53,975 DEBUG   HandlerThread:1475475 [handler.py:handle_request():158] handle_request: internal_messages
2024-10-21 15:56:58,982 DEBUG   HandlerThread:1475475 [handler.py:handle_request():158] handle_request: keepalive
2024-10-21 15:57:03,976 DEBUG   HandlerThread:1475475 [handler.py:handle_request():158] handle_request: internal_messages
2024-10-21 15:57:05,096 INFO    wandb-upload_0:1475475 [retry.py:__call__():172] Retry attempt failed:
Traceback (most recent call last):
  File "/home/zwling/.conda/envs/lzw/lib/python3.10/site-packages/urllib3/connection.py", line 196, in _new_conn
    sock = connection.create_connection(
  File "/home/zwling/.conda/envs/lzw/lib/python3.10/site-packages/urllib3/util/connection.py", line 85, in create_connection
    raise err
  File "/home/zwling/.conda/envs/lzw/lib/python3.10/site-packages/urllib3/util/connection.py", line 73, in create_connection
    sock.connect(sa)
TimeoutError: timed out

The above exception was the direct cause of the following exception:

Traceback (most recent call last):
  File "/home/zwling/.conda/envs/lzw/lib/python3.10/site-packages/urllib3/connectionpool.py", line 789, in urlopen
    response = self._make_request(
  File "/home/zwling/.conda/envs/lzw/lib/python3.10/site-packages/urllib3/connectionpool.py", line 490, in _make_request
    raise new_e
  File "/home/zwling/.conda/envs/lzw/lib/python3.10/site-packages/urllib3/connectionpool.py", line 466, in _make_request
    self._validate_conn(conn)
  File "/home/zwling/.conda/envs/lzw/lib/python3.10/site-packages/urllib3/connectionpool.py", line 1095, in _validate_conn
    conn.connect()
  File "/home/zwling/.conda/envs/lzw/lib/python3.10/site-packages/urllib3/connection.py", line 615, in connect
    self.sock = sock = self._new_conn()
  File "/home/zwling/.conda/envs/lzw/lib/python3.10/site-packages/urllib3/connection.py", line 205, in _new_conn
    raise ConnectTimeoutError(
urllib3.exceptions.ConnectTimeoutError: (<urllib3.connection.HTTPSConnection object at 0x7fe149107550>, 'Connection to api.wandb.ai timed out. (connect timeout=20)')

The above exception was the direct cause of the following exception:

Traceback (most recent call last):
  File "/home/zwling/.conda/envs/lzw/lib/python3.10/site-packages/requests/adapters.py", line 667, in send
    resp = conn.urlopen(
  File "/home/zwling/.conda/envs/lzw/lib/python3.10/site-packages/urllib3/connectionpool.py", line 843, in urlopen
    retries = retries.increment(
  File "/home/zwling/.conda/envs/lzw/lib/python3.10/site-packages/urllib3/util/retry.py", line 519, in increment
    raise MaxRetryError(_pool, url, reason) from reason  # type: ignore[arg-type]
urllib3.exceptions.MaxRetryError: HTTPSConnectionPool(host='api.wandb.ai', port=443): Max retries exceeded with url: /graphql (Caused by ConnectTimeoutError(<urllib3.connection.HTTPSConnection object at 0x7fe149107550>, 'Connection to api.wandb.ai timed out. (connect timeout=20)'))

During handling of the above exception, another exception occurred:

Traceback (most recent call last):
  File "/home/zwling/.conda/envs/lzw/lib/python3.10/site-packages/wandb/sdk/lib/retry.py", line 131, in __call__
    result = self._call_fn(*args, **kwargs)
  File "/home/zwling/.conda/envs/lzw/lib/python3.10/site-packages/wandb/sdk/internal/internal_api.py", line 345, in execute
    return self.client.execute(*args, **kwargs)  # type: ignore
  File "/home/zwling/.conda/envs/lzw/lib/python3.10/site-packages/wandb/vendor/gql-0.2.0/wandb_gql/client.py", line 52, in execute
    result = self._get_result(document, *args, **kwargs)
  File "/home/zwling/.conda/envs/lzw/lib/python3.10/site-packages/wandb/vendor/gql-0.2.0/wandb_gql/client.py", line 60, in _get_result
    return self.transport.execute(document, *args, **kwargs)
  File "/home/zwling/.conda/envs/lzw/lib/python3.10/site-packages/wandb/sdk/lib/gql_request.py", line 58, in execute
    request = self.session.post(self.url, **post_args)
  File "/home/zwling/.conda/envs/lzw/lib/python3.10/site-packages/requests/sessions.py", line 637, in post
    return self.request("POST", url, data=data, json=json, **kwargs)
  File "/home/zwling/.conda/envs/lzw/lib/python3.10/site-packages/requests/sessions.py", line 589, in request
    resp = self.send(prep, **send_kwargs)
  File "/home/zwling/.conda/envs/lzw/lib/python3.10/site-packages/requests/sessions.py", line 703, in send
    r = adapter.send(request, **kwargs)
  File "/home/zwling/.conda/envs/lzw/lib/python3.10/site-packages/requests/adapters.py", line 688, in send
    raise ConnectTimeout(e, request=request)
requests.exceptions.ConnectTimeout: HTTPSConnectionPool(host='api.wandb.ai', port=443): Max retries exceeded with url: /graphql (Caused by ConnectTimeoutError(<urllib3.connection.HTTPSConnection object at 0x7fe149107550>, 'Connection to api.wandb.ai timed out. (connect timeout=20)'))
2024-10-21 15:57:05,099 INFO    SenderThread:1475475 [retry.py:__call__():172] Retry attempt failed:
Traceback (most recent call last):
  File "/home/zwling/.conda/envs/lzw/lib/python3.10/site-packages/urllib3/connection.py", line 196, in _new_conn
    sock = connection.create_connection(
  File "/home/zwling/.conda/envs/lzw/lib/python3.10/site-packages/urllib3/util/connection.py", line 85, in create_connection
    raise err
  File "/home/zwling/.conda/envs/lzw/lib/python3.10/site-packages/urllib3/util/connection.py", line 73, in create_connection
    sock.connect(sa)
TimeoutError: timed out

The above exception was the direct cause of the following exception:

Traceback (most recent call last):
  File "/home/zwling/.conda/envs/lzw/lib/python3.10/site-packages/urllib3/connectionpool.py", line 789, in urlopen
    response = self._make_request(
  File "/home/zwling/.conda/envs/lzw/lib/python3.10/site-packages/urllib3/connectionpool.py", line 490, in _make_request
    raise new_e
  File "/home/zwling/.conda/envs/lzw/lib/python3.10/site-packages/urllib3/connectionpool.py", line 466, in _make_request
    self._validate_conn(conn)
  File "/home/zwling/.conda/envs/lzw/lib/python3.10/site-packages/urllib3/connectionpool.py", line 1095, in _validate_conn
    conn.connect()
  File "/home/zwling/.conda/envs/lzw/lib/python3.10/site-packages/urllib3/connection.py", line 615, in connect
    self.sock = sock = self._new_conn()
  File "/home/zwling/.conda/envs/lzw/lib/python3.10/site-packages/urllib3/connection.py", line 205, in _new_conn
    raise ConnectTimeoutError(
urllib3.exceptions.ConnectTimeoutError: (<urllib3.connection.HTTPSConnection object at 0x7fe149107700>, 'Connection to api.wandb.ai timed out. (connect timeout=20)')

The above exception was the direct cause of the following exception:

Traceback (most recent call last):
  File "/home/zwling/.conda/envs/lzw/lib/python3.10/site-packages/requests/adapters.py", line 667, in send
    resp = conn.urlopen(
  File "/home/zwling/.conda/envs/lzw/lib/python3.10/site-packages/urllib3/connectionpool.py", line 843, in urlopen
    retries = retries.increment(
  File "/home/zwling/.conda/envs/lzw/lib/python3.10/site-packages/urllib3/util/retry.py", line 519, in increment
    raise MaxRetryError(_pool, url, reason) from reason  # type: ignore[arg-type]
urllib3.exceptions.MaxRetryError: HTTPSConnectionPool(host='api.wandb.ai', port=443): Max retries exceeded with url: /graphql (Caused by ConnectTimeoutError(<urllib3.connection.HTTPSConnection object at 0x7fe149107700>, 'Connection to api.wandb.ai timed out. (connect timeout=20)'))

During handling of the above exception, another exception occurred:

Traceback (most recent call last):
  File "/home/zwling/.conda/envs/lzw/lib/python3.10/site-packages/wandb/sdk/lib/retry.py", line 131, in __call__
    result = self._call_fn(*args, **kwargs)
  File "/home/zwling/.conda/envs/lzw/lib/python3.10/site-packages/wandb/sdk/internal/internal_api.py", line 345, in execute
    return self.client.execute(*args, **kwargs)  # type: ignore
  File "/home/zwling/.conda/envs/lzw/lib/python3.10/site-packages/wandb/vendor/gql-0.2.0/wandb_gql/client.py", line 52, in execute
    result = self._get_result(document, *args, **kwargs)
  File "/home/zwling/.conda/envs/lzw/lib/python3.10/site-packages/wandb/vendor/gql-0.2.0/wandb_gql/client.py", line 60, in _get_result
    return self.transport.execute(document, *args, **kwargs)
  File "/home/zwling/.conda/envs/lzw/lib/python3.10/site-packages/wandb/sdk/lib/gql_request.py", line 58, in execute
    request = self.session.post(self.url, **post_args)
  File "/home/zwling/.conda/envs/lzw/lib/python3.10/site-packages/requests/sessions.py", line 637, in post
    return self.request("POST", url, data=data, json=json, **kwargs)
  File "/home/zwling/.conda/envs/lzw/lib/python3.10/site-packages/requests/sessions.py", line 589, in request
    resp = self.send(prep, **send_kwargs)
  File "/home/zwling/.conda/envs/lzw/lib/python3.10/site-packages/requests/sessions.py", line 703, in send
    r = adapter.send(request, **kwargs)
  File "/home/zwling/.conda/envs/lzw/lib/python3.10/site-packages/requests/adapters.py", line 688, in send
    raise ConnectTimeout(e, request=request)
requests.exceptions.ConnectTimeout: HTTPSConnectionPool(host='api.wandb.ai', port=443): Max retries exceeded with url: /graphql (Caused by ConnectTimeoutError(<urllib3.connection.HTTPSConnection object at 0x7fe149107700>, 'Connection to api.wandb.ai timed out. (connect timeout=20)'))
2024-10-21 15:57:08,985 DEBUG   HandlerThread:1475475 [handler.py:handle_request():158] handle_request: keepalive
2024-10-21 15:57:13,976 DEBUG   HandlerThread:1475475 [handler.py:handle_request():158] handle_request: internal_messages
2024-10-21 15:57:18,988 DEBUG   HandlerThread:1475475 [handler.py:handle_request():158] handle_request: keepalive
2024-10-21 15:57:18,988 DEBUG   HandlerThread:1475475 [handler.py:handle_request():158] handle_request: keepalive
2024-10-21 15:57:21,083 DEBUG   SystemMonitor:1475475 [system_monitor.py:_start():172] Starting system metrics aggregation loop
2024-10-21 15:57:23,977 DEBUG   HandlerThread:1475475 [handler.py:handle_request():158] handle_request: internal_messages
2024-10-21 15:57:28,991 DEBUG   HandlerThread:1475475 [handler.py:handle_request():158] handle_request: keepalive
2024-10-21 15:57:28,991 DEBUG   HandlerThread:1475475 [handler.py:handle_request():158] handle_request: keepalive
2024-10-21 15:57:33,977 DEBUG   HandlerThread:1475475 [handler.py:handle_request():158] handle_request: internal_messages
2024-10-21 15:57:39,012 DEBUG   HandlerThread:1475475 [handler.py:handle_request():158] handle_request: keepalive
2024-10-21 15:57:39,012 DEBUG   HandlerThread:1475475 [handler.py:handle_request():158] handle_request: keepalive
2024-10-21 15:57:43,977 DEBUG   HandlerThread:1475475 [handler.py:handle_request():158] handle_request: internal_messages
2024-10-21 15:57:49,015 DEBUG   HandlerThread:1475475 [handler.py:handle_request():158] handle_request: keepalive
2024-10-21 15:57:49,016 DEBUG   HandlerThread:1475475 [handler.py:handle_request():158] handle_request: keepalive
2024-10-21 15:57:53,977 DEBUG   HandlerThread:1475475 [handler.py:handle_request():158] handle_request: internal_messages
2024-10-21 15:57:59,018 DEBUG   HandlerThread:1475475 [handler.py:handle_request():158] handle_request: keepalive
2024-10-21 15:57:59,018 DEBUG   HandlerThread:1475475 [handler.py:handle_request():158] handle_request: keepalive
2024-10-21 15:58:03,977 DEBUG   HandlerThread:1475475 [handler.py:handle_request():158] handle_request: internal_messages
2024-10-21 15:58:04,258 DEBUG   HandlerThread:1475475 [handler.py:handle_request():158] handle_request: partial_history
2024-10-21 15:58:05,262 DEBUG   HandlerThread:1475475 [handler.py:handle_request():158] handle_request: poll_exit
2024-10-21 15:58:10,267 DEBUG   HandlerThread:1475475 [handler.py:handle_request():158] handle_request: keepalive
2024-10-21 15:58:15,272 DEBUG   HandlerThread:1475475 [handler.py:handle_request():158] handle_request: keepalive
2024-10-21 15:58:20,274 DEBUG   HandlerThread:1475475 [handler.py:handle_request():158] handle_request: keepalive
2024-10-21 15:58:25,277 DEBUG   HandlerThread:1475475 [handler.py:handle_request():158] handle_request: keepalive
2024-10-21 15:58:30,279 DEBUG   HandlerThread:1475475 [handler.py:handle_request():158] handle_request: keepalive
2024-10-21 15:58:35,281 DEBUG   HandlerThread:1475475 [handler.py:handle_request():158] handle_request: keepalive
2024-10-21 15:58:40,283 DEBUG   HandlerThread:1475475 [handler.py:handle_request():158] handle_request: keepalive
2024-10-21 15:58:45,285 DEBUG   HandlerThread:1475475 [handler.py:handle_request():158] handle_request: keepalive
2024-10-21 15:58:50,286 DEBUG   HandlerThread:1475475 [handler.py:handle_request():158] handle_request: keepalive
2024-10-21 15:58:55,288 DEBUG   HandlerThread:1475475 [handler.py:handle_request():158] handle_request: keepalive
2024-10-21 15:59:00,290 DEBUG   HandlerThread:1475475 [handler.py:handle_request():158] handle_request: keepalive
2024-10-21 15:59:00,768 WARNING FileStreamThread:1475475 [file_stream.py:request_with_retry():674] requests_with_retry encountered retryable exception: HTTPSConnectionPool(host='api.wandb.ai', port=443): Max retries exceeded with url: /files/zwling/ood-record/78bh6aux/file_stream (Caused by ConnectTimeoutError(<urllib3.connection.HTTPSConnection object at 0x7fe149106d70>, 'Connection to api.wandb.ai timed out. (connect timeout=None)')). func: <bound method Session.post of <requests.sessions.Session object at 0x7fe139738ac0>>, args: ('https://api.wandb.ai/files/zwling/ood-record/78bh6aux/file_stream',), kwargs: {'json': {'complete': False, 'failed': False, 'dropped': 0, 'uploaded': []}}
2024-10-21 15:59:05,292 DEBUG   HandlerThread:1475475 [handler.py:handle_request():158] handle_request: keepalive
2024-10-21 15:59:10,294 DEBUG   HandlerThread:1475475 [handler.py:handle_request():158] handle_request: keepalive
2024-10-21 15:59:15,296 DEBUG   HandlerThread:1475475 [handler.py:handle_request():158] handle_request: keepalive
2024-10-21 15:59:20,299 DEBUG   HandlerThread:1475475 [handler.py:handle_request():158] handle_request: keepalive
2024-10-21 15:59:25,301 DEBUG   HandlerThread:1475475 [handler.py:handle_request():158] handle_request: keepalive
2024-10-21 15:59:30,303 DEBUG   HandlerThread:1475475 [handler.py:handle_request():158] handle_request: keepalive
2024-10-21 15:59:35,305 DEBUG   HandlerThread:1475475 [handler.py:handle_request():158] handle_request: keepalive
2024-10-21 15:59:40,307 DEBUG   HandlerThread:1475475 [handler.py:handle_request():158] handle_request: keepalive
2024-10-21 15:59:45,309 DEBUG   HandlerThread:1475475 [handler.py:handle_request():158] handle_request: keepalive
2024-10-21 15:59:50,311 DEBUG   HandlerThread:1475475 [handler.py:handle_request():158] handle_request: keepalive
2024-10-21 15:59:55,314 DEBUG   HandlerThread:1475475 [handler.py:handle_request():158] handle_request: keepalive
2024-10-21 16:00:00,316 DEBUG   HandlerThread:1475475 [handler.py:handle_request():158] handle_request: keepalive
2024-10-21 16:00:05,318 DEBUG   HandlerThread:1475475 [handler.py:handle_request():158] handle_request: keepalive
2024-10-21 16:00:10,320 DEBUG   HandlerThread:1475475 [handler.py:handle_request():158] handle_request: keepalive
2024-10-21 16:00:15,322 DEBUG   HandlerThread:1475475 [handler.py:handle_request():158] handle_request: keepalive
2024-10-21 16:00:20,324 DEBUG   HandlerThread:1475475 [handler.py:handle_request():158] handle_request: keepalive
2024-10-21 16:00:25,326 DEBUG   HandlerThread:1475475 [handler.py:handle_request():158] handle_request: keepalive
2024-10-21 16:00:30,328 DEBUG   HandlerThread:1475475 [handler.py:handle_request():158] handle_request: keepalive
2024-10-21 16:00:35,330 DEBUG   HandlerThread:1475475 [handler.py:handle_request():158] handle_request: keepalive
2024-10-21 16:00:40,331 DEBUG   HandlerThread:1475475 [handler.py:handle_request():158] handle_request: keepalive
2024-10-21 16:00:45,333 DEBUG   HandlerThread:1475475 [handler.py:handle_request():158] handle_request: keepalive
2024-10-21 16:00:50,335 DEBUG   HandlerThread:1475475 [handler.py:handle_request():158] handle_request: keepalive
2024-10-21 16:00:55,338 DEBUG   HandlerThread:1475475 [handler.py:handle_request():158] handle_request: keepalive
2024-10-21 16:01:00,340 DEBUG   HandlerThread:1475475 [handler.py:handle_request():158] handle_request: keepalive
2024-10-21 16:01:05,342 DEBUG   HandlerThread:1475475 [handler.py:handle_request():158] handle_request: keepalive
2024-10-21 16:01:10,344 DEBUG   HandlerThread:1475475 [handler.py:handle_request():158] handle_request: keepalive
2024-10-21 16:01:13,891 WARNING FileStreamThread:1475475 [file_stream.py:request_with_retry():674] requests_with_retry encountered retryable exception: HTTPSConnectionPool(host='api.wandb.ai', port=443): Max retries exceeded with url: /files/zwling/ood-record/78bh6aux/file_stream (Caused by ConnectTimeoutError(<urllib3.connection.HTTPSConnection object at 0x7fe13976e740>, 'Connection to api.wandb.ai timed out. (connect timeout=None)')). func: <bound method Session.post of <requests.sessions.Session object at 0x7fe139738ac0>>, args: ('https://api.wandb.ai/files/zwling/ood-record/78bh6aux/file_stream',), kwargs: {'json': {'complete': False, 'failed': False, 'dropped': 0, 'uploaded': []}}
2024-10-21 16:01:15,346 DEBUG   HandlerThread:1475475 [handler.py:handle_request():158] handle_request: keepalive
2024-10-21 16:01:20,348 DEBUG   HandlerThread:1475475 [handler.py:handle_request():158] handle_request: keepalive
2024-10-21 16:01:25,350 DEBUG   HandlerThread:1475475 [handler.py:handle_request():158] handle_request: keepalive
2024-10-21 16:01:30,352 DEBUG   HandlerThread:1475475 [handler.py:handle_request():158] handle_request: keepalive
2024-10-21 16:01:35,355 DEBUG   HandlerThread:1475475 [handler.py:handle_request():158] handle_request: keepalive
2024-10-21 16:01:40,357 DEBUG   HandlerThread:1475475 [handler.py:handle_request():158] handle_request: keepalive
2024-10-21 16:01:45,359 DEBUG   HandlerThread:1475475 [handler.py:handle_request():158] handle_request: keepalive
2024-10-21 16:01:50,361 DEBUG   HandlerThread:1475475 [handler.py:handle_request():158] handle_request: keepalive
2024-10-21 16:01:55,363 DEBUG   HandlerThread:1475475 [handler.py:handle_request():158] handle_request: keepalive
2024-10-21 16:02:00,365 DEBUG   HandlerThread:1475475 [handler.py:handle_request():158] handle_request: keepalive
2024-10-21 16:02:05,367 DEBUG   HandlerThread:1475475 [handler.py:handle_request():158] handle_request: keepalive
2024-10-21 16:02:10,369 DEBUG   HandlerThread:1475475 [handler.py:handle_request():158] handle_request: keepalive
2024-10-21 16:02:15,371 DEBUG   HandlerThread:1475475 [handler.py:handle_request():158] handle_request: keepalive
2024-10-21 16:02:20,373 DEBUG   HandlerThread:1475475 [handler.py:handle_request():158] handle_request: keepalive
2024-10-21 16:02:25,375 DEBUG   HandlerThread:1475475 [handler.py:handle_request():158] handle_request: keepalive
2024-10-21 16:02:30,378 DEBUG   HandlerThread:1475475 [handler.py:handle_request():158] handle_request: keepalive
2024-10-21 16:02:35,380 DEBUG   HandlerThread:1475475 [handler.py:handle_request():158] handle_request: keepalive
2024-10-21 16:02:40,382 DEBUG   HandlerThread:1475475 [handler.py:handle_request():158] handle_request: keepalive
2024-10-21 16:02:45,384 DEBUG   HandlerThread:1475475 [handler.py:handle_request():158] handle_request: keepalive
2024-10-21 16:02:50,386 DEBUG   HandlerThread:1475475 [handler.py:handle_request():158] handle_request: keepalive
2024-10-21 16:02:55,388 DEBUG   HandlerThread:1475475 [handler.py:handle_request():158] handle_request: keepalive
2024-10-21 16:03:00,390 DEBUG   HandlerThread:1475475 [handler.py:handle_request():158] handle_request: keepalive
2024-10-21 16:03:05,392 DEBUG   HandlerThread:1475475 [handler.py:handle_request():158] handle_request: keepalive
2024-10-21 16:03:10,395 DEBUG   HandlerThread:1475475 [handler.py:handle_request():158] handle_request: keepalive
2024-10-21 16:03:15,397 DEBUG   HandlerThread:1475475 [handler.py:handle_request():158] handle_request: keepalive
2024-10-21 16:03:20,399 DEBUG   HandlerThread:1475475 [handler.py:handle_request():158] handle_request: keepalive
2024-10-21 16:03:25,401 DEBUG   HandlerThread:1475475 [handler.py:handle_request():158] handle_request: keepalive
2024-10-21 16:03:29,060 WARNING FileStreamThread:1475475 [file_stream.py:request_with_retry():674] requests_with_retry encountered retryable exception: HTTPSConnectionPool(host='api.wandb.ai', port=443): Max retries exceeded with url: /files/zwling/ood-record/78bh6aux/file_stream (Caused by ConnectTimeoutError(<urllib3.connection.HTTPSConnection object at 0x7fe1397381f0>, 'Connection to api.wandb.ai timed out. (connect timeout=None)')). func: <bound method Session.post of <requests.sessions.Session object at 0x7fe139738ac0>>, args: ('https://api.wandb.ai/files/zwling/ood-record/78bh6aux/file_stream',), kwargs: {'json': {'complete': False, 'failed': False, 'dropped': 0, 'uploaded': []}}
2024-10-21 16:03:30,403 DEBUG   HandlerThread:1475475 [handler.py:handle_request():158] handle_request: keepalive
2024-10-21 16:03:35,406 DEBUG   HandlerThread:1475475 [handler.py:handle_request():158] handle_request: keepalive
2024-10-21 16:03:40,408 DEBUG   HandlerThread:1475475 [handler.py:handle_request():158] handle_request: keepalive
2024-10-21 16:03:45,410 DEBUG   HandlerThread:1475475 [handler.py:handle_request():158] handle_request: keepalive
2024-10-21 16:03:50,411 DEBUG   HandlerThread:1475475 [handler.py:handle_request():158] handle_request: keepalive
2024-10-21 16:03:55,413 DEBUG   HandlerThread:1475475 [handler.py:handle_request():158] handle_request: keepalive
2024-10-21 16:04:00,415 DEBUG   HandlerThread:1475475 [handler.py:handle_request():158] handle_request: keepalive
2024-10-21 16:04:05,418 DEBUG   HandlerThread:1475475 [handler.py:handle_request():158] handle_request: keepalive
2024-10-21 16:04:10,420 DEBUG   HandlerThread:1475475 [handler.py:handle_request():158] handle_request: keepalive
2024-10-21 16:04:15,267 INFO    memory    :1475475 [interfaces.py:monitor():138] Process proc.memory.rssMB has exited.
2024-10-21 16:04:15,271 DEBUG   SystemMonitor:1475475 [system_monitor.py:_start():179] Finished system metrics aggregation loop
2024-10-21 16:04:15,271 DEBUG   SystemMonitor:1475475 [system_monitor.py:_start():183] Publishing last batch of metrics
2024-10-21 16:04:15,422 DEBUG   HandlerThread:1475475 [handler.py:handle_request():158] handle_request: keepalive
2024-10-21 16:04:16,548 WARNING StreamThr :1475475 [internal.py:is_dead():413] Internal process exiting, parent pid 1475452 disappeared
2024-10-21 16:04:16,548 ERROR   StreamThr :1475475 [internal.py:wandb_internal():151] Internal process shutdown.
2024-10-21 16:04:17,276 INFO    WriterThread:1475475 [datastore.py:close():296] close: /home/zwling/code/OOD-Libraries/wandb/run-20241021_155510-78bh6aux/run-78bh6aux.wandb
2024-10-21 16:04:17,422 INFO    HandlerThread:1475475 [handler.py:finish():884] shutting down handler
2024-10-21 16:04:17,423 INFO    HandlerThread:1475475 [system_monitor.py:finish():203] Stopping system monitor
2024-10-21 16:04:17,423 INFO    HandlerThread:1475475 [interfaces.py:finish():200] Joined cpu monitor
2024-10-21 16:04:17,423 INFO    HandlerThread:1475475 [interfaces.py:finish():200] Joined disk monitor
2024-10-21 16:04:17,423 INFO    HandlerThread:1475475 [interfaces.py:finish():200] Joined gpu monitor
2024-10-21 16:04:17,424 INFO    HandlerThread:1475475 [interfaces.py:finish():200] Joined memory monitor
2024-10-21 16:04:17,424 INFO    HandlerThread:1475475 [interfaces.py:finish():200] Joined network monitor
2024-10-21 16:05:48,320 WARNING FileStreamThread:1475475 [file_stream.py:request_with_retry():674] requests_with_retry encountered retryable exception: HTTPSConnectionPool(host='api.wandb.ai', port=443): Max retries exceeded with url: /files/zwling/ood-record/78bh6aux/file_stream (Caused by ConnectTimeoutError(<urllib3.connection.HTTPSConnection object at 0x7fe149107e50>, 'Connection to api.wandb.ai timed out. (connect timeout=None)')). func: <bound method Session.post of <requests.sessions.Session object at 0x7fe139738ac0>>, args: ('https://api.wandb.ai/files/zwling/ood-record/78bh6aux/file_stream',), kwargs: {'json': {'complete': False, 'failed': False, 'dropped': 0, 'uploaded': []}}
2024-10-21 16:08:15,776 WARNING FileStreamThread:1475475 [file_stream.py:request_with_retry():674] requests_with_retry encountered retryable exception: HTTPSConnectionPool(host='api.wandb.ai', port=443): Max retries exceeded with url: /files/zwling/ood-record/78bh6aux/file_stream (Caused by ConnectTimeoutError(<urllib3.connection.HTTPSConnection object at 0x7fe138630940>, 'Connection to api.wandb.ai timed out. (connect timeout=None)')). func: <bound method Session.post of <requests.sessions.Session object at 0x7fe139738ac0>>, args: ('https://api.wandb.ai/files/zwling/ood-record/78bh6aux/file_stream',), kwargs: {'json': {'complete': False, 'failed': False, 'dropped': 0, 'uploaded': []}}
2024-10-21 16:10:59,616 WARNING FileStreamThread:1475475 [file_stream.py:request_with_retry():674] requests_with_retry encountered retryable exception: HTTPSConnectionPool(host='api.wandb.ai', port=443): Max retries exceeded with url: /files/zwling/ood-record/78bh6aux/file_stream (Caused by ConnectTimeoutError(<urllib3.connection.HTTPSConnection object at 0x7fe1491065f0>, 'Connection to api.wandb.ai timed out. (connect timeout=None)')). func: <bound method Session.post of <requests.sessions.Session object at 0x7fe139738ac0>>, args: ('https://api.wandb.ai/files/zwling/ood-record/78bh6aux/file_stream',), kwargs: {'json': {'complete': False, 'failed': False, 'dropped': 0, 'uploaded': []}}
2024-10-21 16:14:24,416 WARNING FileStreamThread:1475475 [file_stream.py:request_with_retry():674] requests_with_retry encountered retryable exception: HTTPSConnectionPool(host='api.wandb.ai', port=443): Max retries exceeded with url: /files/zwling/ood-record/78bh6aux/file_stream (Caused by ConnectTimeoutError(<urllib3.connection.HTTPSConnection object at 0x7fe138633340>, 'Connection to api.wandb.ai timed out. (connect timeout=None)')). func: <bound method Session.post of <requests.sessions.Session object at 0x7fe139738ac0>>, args: ('https://api.wandb.ai/files/zwling/ood-record/78bh6aux/file_stream',), kwargs: {'json': {'complete': False, 'failed': False, 'dropped': 0, 'uploaded': []}}
2024-10-21 16:18:50,656 WARNING FileStreamThread:1475475 [file_stream.py:request_with_retry():674] requests_with_retry encountered retryable exception: HTTPSConnectionPool(host='api.wandb.ai', port=443): Max retries exceeded with url: /files/zwling/ood-record/78bh6aux/file_stream (Caused by ConnectTimeoutError(<urllib3.connection.HTTPSConnection object at 0x7fe139738670>, 'Connection to api.wandb.ai timed out. (connect timeout=None)')). func: <bound method Session.post of <requests.sessions.Session object at 0x7fe139738ac0>>, args: ('https://api.wandb.ai/files/zwling/ood-record/78bh6aux/file_stream',), kwargs: {'json': {'complete': False, 'failed': False, 'dropped': 0, 'uploaded': []}}
2024-10-21 16:33:06,872 WARNING FileStreamThread:1475475 [file_stream.py:request_with_retry():674] requests_with_retry encountered retryable exception: ('Connection aborted.', RemoteDisconnected('Remote end closed connection without response')). func: <bound method Session.post of <requests.sessions.Session object at 0x7fe139738ac0>>, args: ('https://api.wandb.ai/files/zwling/ood-record/78bh6aux/file_stream',), kwargs: {'json': {'complete': False, 'failed': False, 'dropped': 0, 'uploaded': []}}
2024-10-21 16:40:12,306 INFO    SenderThread:1475475 [sender.py:finish():1631] shutting down sender
2024-10-21 16:40:12,306 INFO    SenderThread:1475475 [dir_watcher.py:finish():358] shutting down directory watcher
2024-10-21 16:40:12,600 INFO    SenderThread:1475475 [dir_watcher.py:finish():388] scan: /home/zwling/code/OOD-Libraries/wandb/run-20241021_155510-78bh6aux/files
2024-10-21 16:40:12,601 INFO    SenderThread:1475475 [dir_watcher.py:finish():402] scan save: /home/zwling/code/OOD-Libraries/wandb/run-20241021_155510-78bh6aux/files/wandb-metadata.json wandb-metadata.json
2024-10-21 16:40:12,601 INFO    SenderThread:1475475 [dir_watcher.py:finish():402] scan save: /home/zwling/code/OOD-Libraries/wandb/run-20241021_155510-78bh6aux/files/conda-environment.yaml conda-environment.yaml
2024-10-21 16:40:12,602 INFO    SenderThread:1475475 [dir_watcher.py:finish():402] scan save: /home/zwling/code/OOD-Libraries/wandb/run-20241021_155510-78bh6aux/files/requirements.txt requirements.txt
2024-10-21 16:40:12,607 INFO    SenderThread:1475475 [dir_watcher.py:finish():402] scan save: /home/zwling/code/OOD-Libraries/wandb/run-20241021_155510-78bh6aux/files/config.yaml config.yaml
2024-10-21 16:40:12,608 INFO    SenderThread:1475475 [file_pusher.py:finish():169] shutting down file pusher
2024-10-21 16:40:12,608 INFO    SenderThread:1475475 [file_pusher.py:join():175] waiting for file pusher
2024-10-21 16:40:13,038 ERROR   wandb-upload_1:1475475 [internal_api.py:execute():349] 404 response executing GraphQL.
2024-10-21 16:40:13,039 ERROR   wandb-upload_1:1475475 [internal_api.py:execute():350] {"errors":[{"message":"run ood-record/78bh6aux not found during createRunFiles","path":["createRunFiles"]}],"data":{"createRunFiles":null}}
2024-10-21 16:40:13,039 ERROR   Thread-11 (_thread_body):1475475 [step_upload.py:_handle_event():144] Failed to upload file: /home/zwling/code/OOD-Libraries/wandb/run-20241021_155510-78bh6aux/files/conda-environment.yaml
Traceback (most recent call last):
  File "/home/zwling/.conda/envs/lzw/lib/python3.10/site-packages/wandb/sdk/internal/internal_api.py", line 345, in execute
    return self.client.execute(*args, **kwargs)  # type: ignore
  File "/home/zwling/.conda/envs/lzw/lib/python3.10/site-packages/wandb/vendor/gql-0.2.0/wandb_gql/client.py", line 52, in execute
    result = self._get_result(document, *args, **kwargs)
  File "/home/zwling/.conda/envs/lzw/lib/python3.10/site-packages/wandb/vendor/gql-0.2.0/wandb_gql/client.py", line 60, in _get_result
    return self.transport.execute(document, *args, **kwargs)
  File "/home/zwling/.conda/envs/lzw/lib/python3.10/site-packages/wandb/sdk/lib/gql_request.py", line 59, in execute
    request.raise_for_status()
  File "/home/zwling/.conda/envs/lzw/lib/python3.10/site-packages/requests/models.py", line 1024, in raise_for_status
    raise HTTPError(http_error_msg, response=self)
requests.exceptions.HTTPError: 404 Client Error: Not Found for url: https://api.wandb.ai/graphql

During handling of the above exception, another exception occurred:

Traceback (most recent call last):
  File "/home/zwling/.conda/envs/lzw/lib/python3.10/site-packages/wandb/apis/normalize.py", line 41, in wrapper
    return func(*args, **kwargs)
  File "/home/zwling/.conda/envs/lzw/lib/python3.10/site-packages/wandb/sdk/internal/internal_api.py", line 2500, in upload_urls
    query_result = self.gql(
  File "/home/zwling/.conda/envs/lzw/lib/python3.10/site-packages/wandb/sdk/internal/internal_api.py", line 317, in gql
    ret = self._retry_gql(
  File "/home/zwling/.conda/envs/lzw/lib/python3.10/site-packages/wandb/sdk/lib/retry.py", line 131, in __call__
    result = self._call_fn(*args, **kwargs)
  File "/home/zwling/.conda/envs/lzw/lib/python3.10/site-packages/wandb/sdk/internal/internal_api.py", line 352, in execute
    wandb.termerror(f"Error while calling W&B API: {error} ({response})")
  File "/home/zwling/.conda/envs/lzw/lib/python3.10/site-packages/wandb/errors/term.py", line 64, in termerror
    _log(
  File "/home/zwling/.conda/envs/lzw/lib/python3.10/site-packages/wandb/errors/term.py", line 103, in _log
    click.echo(line, file=sys.stderr, nl=newline)
  File "/home/zwling/.conda/envs/lzw/lib/python3.10/site-packages/click/utils.py", line 318, in echo
    file.write(out)  # type: ignore
OSError: [Errno 5] Input/output error

During handling of the above exception, another exception occurred:

Traceback (most recent call last):
  File "/home/zwling/.conda/envs/lzw/lib/python3.10/concurrent/futures/thread.py", line 58, in run
    result = self.fn(*self.args, **self.kwargs)
  File "/home/zwling/.conda/envs/lzw/lib/python3.10/site-packages/wandb/filesync/step_upload.py", line 223, in run_and_notify
    self._do_upload(event)
  File "/home/zwling/.conda/envs/lzw/lib/python3.10/site-packages/wandb/filesync/step_upload.py", line 243, in _do_upload
    job.run()
  File "/home/zwling/.conda/envs/lzw/lib/python3.10/site-packages/wandb/filesync/upload_job.py", line 56, in run
    self.push()
  File "/home/zwling/.conda/envs/lzw/lib/python3.10/site-packages/wandb/filesync/upload_job.py", line 105, in push
    _, upload_headers, result = self._api.upload_urls(project, [self.save_name])
  File "/home/zwling/.conda/envs/lzw/lib/python3.10/site-packages/wandb/apis/normalize.py", line 87, in wrapper
    raise CommError(message, err).with_traceback(sys.exc_info()[2])
  File "/home/zwling/.conda/envs/lzw/lib/python3.10/site-packages/wandb/apis/normalize.py", line 41, in wrapper
    return func(*args, **kwargs)
  File "/home/zwling/.conda/envs/lzw/lib/python3.10/site-packages/wandb/sdk/internal/internal_api.py", line 2500, in upload_urls
    query_result = self.gql(
  File "/home/zwling/.conda/envs/lzw/lib/python3.10/site-packages/wandb/sdk/internal/internal_api.py", line 317, in gql
    ret = self._retry_gql(
  File "/home/zwling/.conda/envs/lzw/lib/python3.10/site-packages/wandb/sdk/lib/retry.py", line 131, in __call__
    result = self._call_fn(*args, **kwargs)
  File "/home/zwling/.conda/envs/lzw/lib/python3.10/site-packages/wandb/sdk/internal/internal_api.py", line 352, in execute
    wandb.termerror(f"Error while calling W&B API: {error} ({response})")
  File "/home/zwling/.conda/envs/lzw/lib/python3.10/site-packages/wandb/errors/term.py", line 64, in termerror
    _log(
  File "/home/zwling/.conda/envs/lzw/lib/python3.10/site-packages/wandb/errors/term.py", line 103, in _log
    click.echo(line, file=sys.stderr, nl=newline)
  File "/home/zwling/.conda/envs/lzw/lib/python3.10/site-packages/click/utils.py", line 318, in echo
    file.write(out)  # type: ignore
wandb.errors.CommError: [Errno 5] Input/output error
2024-10-21 16:40:13,344 ERROR   wandb-upload_3:1475475 [internal_api.py:execute():349] 404 response executing GraphQL.
2024-10-21 16:40:13,344 ERROR   wandb-upload_3:1475475 [internal_api.py:execute():350] {"errors":[{"message":"run ood-record/78bh6aux not found during createRunFiles","path":["createRunFiles"]}],"data":{"createRunFiles":null}}
2024-10-21 16:40:13,345 ERROR   Thread-11 (_thread_body):1475475 [step_upload.py:_handle_event():144] Failed to upload file: /home/zwling/code/OOD-Libraries/wandb/run-20241021_155510-78bh6aux/files/config.yaml
Traceback (most recent call last):
  File "/home/zwling/.conda/envs/lzw/lib/python3.10/site-packages/wandb/sdk/internal/internal_api.py", line 345, in execute
    return self.client.execute(*args, **kwargs)  # type: ignore
  File "/home/zwling/.conda/envs/lzw/lib/python3.10/site-packages/wandb/vendor/gql-0.2.0/wandb_gql/client.py", line 52, in execute
    result = self._get_result(document, *args, **kwargs)
  File "/home/zwling/.conda/envs/lzw/lib/python3.10/site-packages/wandb/vendor/gql-0.2.0/wandb_gql/client.py", line 60, in _get_result
    return self.transport.execute(document, *args, **kwargs)
  File "/home/zwling/.conda/envs/lzw/lib/python3.10/site-packages/wandb/sdk/lib/gql_request.py", line 59, in execute
    request.raise_for_status()
  File "/home/zwling/.conda/envs/lzw/lib/python3.10/site-packages/requests/models.py", line 1024, in raise_for_status
    raise HTTPError(http_error_msg, response=self)
requests.exceptions.HTTPError: 404 Client Error: Not Found for url: https://api.wandb.ai/graphql

During handling of the above exception, another exception occurred:

Traceback (most recent call last):
  File "/home/zwling/.conda/envs/lzw/lib/python3.10/site-packages/wandb/apis/normalize.py", line 41, in wrapper
    return func(*args, **kwargs)
  File "/home/zwling/.conda/envs/lzw/lib/python3.10/site-packages/wandb/sdk/internal/internal_api.py", line 2500, in upload_urls
    query_result = self.gql(
  File "/home/zwling/.conda/envs/lzw/lib/python3.10/site-packages/wandb/sdk/internal/internal_api.py", line 317, in gql
    ret = self._retry_gql(
  File "/home/zwling/.conda/envs/lzw/lib/python3.10/site-packages/wandb/sdk/lib/retry.py", line 131, in __call__
    result = self._call_fn(*args, **kwargs)
  File "/home/zwling/.conda/envs/lzw/lib/python3.10/site-packages/wandb/sdk/internal/internal_api.py", line 352, in execute
    wandb.termerror(f"Error while calling W&B API: {error} ({response})")
  File "/home/zwling/.conda/envs/lzw/lib/python3.10/site-packages/wandb/errors/term.py", line 64, in termerror
    _log(
  File "/home/zwling/.conda/envs/lzw/lib/python3.10/site-packages/wandb/errors/term.py", line 103, in _log
    click.echo(line, file=sys.stderr, nl=newline)
  File "/home/zwling/.conda/envs/lzw/lib/python3.10/site-packages/click/utils.py", line 318, in echo
    file.write(out)  # type: ignore
OSError: [Errno 5] Input/output error

During handling of the above exception, another exception occurred:

Traceback (most recent call last):
  File "/home/zwling/.conda/envs/lzw/lib/python3.10/concurrent/futures/thread.py", line 58, in run
    result = self.fn(*self.args, **self.kwargs)
  File "/home/zwling/.conda/envs/lzw/lib/python3.10/site-packages/wandb/filesync/step_upload.py", line 223, in run_and_notify
    self._do_upload(event)
  File "/home/zwling/.conda/envs/lzw/lib/python3.10/site-packages/wandb/filesync/step_upload.py", line 243, in _do_upload
    job.run()
  File "/home/zwling/.conda/envs/lzw/lib/python3.10/site-packages/wandb/filesync/upload_job.py", line 56, in run
    self.push()
  File "/home/zwling/.conda/envs/lzw/lib/python3.10/site-packages/wandb/filesync/upload_job.py", line 105, in push
    _, upload_headers, result = self._api.upload_urls(project, [self.save_name])
  File "/home/zwling/.conda/envs/lzw/lib/python3.10/site-packages/wandb/apis/normalize.py", line 87, in wrapper
    raise CommError(message, err).with_traceback(sys.exc_info()[2])
  File "/home/zwling/.conda/envs/lzw/lib/python3.10/site-packages/wandb/apis/normalize.py", line 41, in wrapper
    return func(*args, **kwargs)
  File "/home/zwling/.conda/envs/lzw/lib/python3.10/site-packages/wandb/sdk/internal/internal_api.py", line 2500, in upload_urls
    query_result = self.gql(
  File "/home/zwling/.conda/envs/lzw/lib/python3.10/site-packages/wandb/sdk/internal/internal_api.py", line 317, in gql
    ret = self._retry_gql(
  File "/home/zwling/.conda/envs/lzw/lib/python3.10/site-packages/wandb/sdk/lib/retry.py", line 131, in __call__
    result = self._call_fn(*args, **kwargs)
  File "/home/zwling/.conda/envs/lzw/lib/python3.10/site-packages/wandb/sdk/internal/internal_api.py", line 352, in execute
    wandb.termerror(f"Error while calling W&B API: {error} ({response})")
  File "/home/zwling/.conda/envs/lzw/lib/python3.10/site-packages/wandb/errors/term.py", line 64, in termerror
    _log(
  File "/home/zwling/.conda/envs/lzw/lib/python3.10/site-packages/wandb/errors/term.py", line 103, in _log
    click.echo(line, file=sys.stderr, nl=newline)
  File "/home/zwling/.conda/envs/lzw/lib/python3.10/site-packages/click/utils.py", line 318, in echo
    file.write(out)  # type: ignore
wandb.errors.CommError: [Errno 5] Input/output error
2024-10-21 16:40:54,440 INFO    wandb-upload_2:1475475 [retry.py:__call__():172] Retry attempt failed:
Traceback (most recent call last):
  File "/home/zwling/.conda/envs/lzw/lib/python3.10/site-packages/urllib3/connection.py", line 196, in _new_conn
    sock = connection.create_connection(
  File "/home/zwling/.conda/envs/lzw/lib/python3.10/site-packages/urllib3/util/connection.py", line 85, in create_connection
    raise err
  File "/home/zwling/.conda/envs/lzw/lib/python3.10/site-packages/urllib3/util/connection.py", line 73, in create_connection
    sock.connect(sa)
TimeoutError: timed out

The above exception was the direct cause of the following exception:

Traceback (most recent call last):
  File "/home/zwling/.conda/envs/lzw/lib/python3.10/site-packages/urllib3/connectionpool.py", line 789, in urlopen
    response = self._make_request(
  File "/home/zwling/.conda/envs/lzw/lib/python3.10/site-packages/urllib3/connectionpool.py", line 490, in _make_request
    raise new_e
  File "/home/zwling/.conda/envs/lzw/lib/python3.10/site-packages/urllib3/connectionpool.py", line 466, in _make_request
    self._validate_conn(conn)
  File "/home/zwling/.conda/envs/lzw/lib/python3.10/site-packages/urllib3/connectionpool.py", line 1095, in _validate_conn
    conn.connect()
  File "/home/zwling/.conda/envs/lzw/lib/python3.10/site-packages/urllib3/connection.py", line 615, in connect
    self.sock = sock = self._new_conn()
  File "/home/zwling/.conda/envs/lzw/lib/python3.10/site-packages/urllib3/connection.py", line 205, in _new_conn
    raise ConnectTimeoutError(
urllib3.exceptions.ConnectTimeoutError: (<urllib3.connection.HTTPSConnection object at 0x7fe149107a00>, 'Connection to api.wandb.ai timed out. (connect timeout=20)')

The above exception was the direct cause of the following exception:

Traceback (most recent call last):
  File "/home/zwling/.conda/envs/lzw/lib/python3.10/site-packages/requests/adapters.py", line 667, in send
    resp = conn.urlopen(
  File "/home/zwling/.conda/envs/lzw/lib/python3.10/site-packages/urllib3/connectionpool.py", line 843, in urlopen
    retries = retries.increment(
  File "/home/zwling/.conda/envs/lzw/lib/python3.10/site-packages/urllib3/util/retry.py", line 519, in increment
    raise MaxRetryError(_pool, url, reason) from reason  # type: ignore[arg-type]
urllib3.exceptions.MaxRetryError: HTTPSConnectionPool(host='api.wandb.ai', port=443): Max retries exceeded with url: /graphql (Caused by ConnectTimeoutError(<urllib3.connection.HTTPSConnection object at 0x7fe149107a00>, 'Connection to api.wandb.ai timed out. (connect timeout=20)'))

During handling of the above exception, another exception occurred:

Traceback (most recent call last):
  File "/home/zwling/.conda/envs/lzw/lib/python3.10/site-packages/wandb/sdk/lib/retry.py", line 131, in __call__
    result = self._call_fn(*args, **kwargs)
  File "/home/zwling/.conda/envs/lzw/lib/python3.10/site-packages/wandb/sdk/internal/internal_api.py", line 345, in execute
    return self.client.execute(*args, **kwargs)  # type: ignore
  File "/home/zwling/.conda/envs/lzw/lib/python3.10/site-packages/wandb/vendor/gql-0.2.0/wandb_gql/client.py", line 52, in execute
    result = self._get_result(document, *args, **kwargs)
  File "/home/zwling/.conda/envs/lzw/lib/python3.10/site-packages/wandb/vendor/gql-0.2.0/wandb_gql/client.py", line 60, in _get_result
    return self.transport.execute(document, *args, **kwargs)
  File "/home/zwling/.conda/envs/lzw/lib/python3.10/site-packages/wandb/sdk/lib/gql_request.py", line 58, in execute
    request = self.session.post(self.url, **post_args)
  File "/home/zwling/.conda/envs/lzw/lib/python3.10/site-packages/requests/sessions.py", line 637, in post
    return self.request("POST", url, data=data, json=json, **kwargs)
  File "/home/zwling/.conda/envs/lzw/lib/python3.10/site-packages/requests/sessions.py", line 589, in request
    resp = self.send(prep, **send_kwargs)
  File "/home/zwling/.conda/envs/lzw/lib/python3.10/site-packages/requests/sessions.py", line 703, in send
    r = adapter.send(request, **kwargs)
  File "/home/zwling/.conda/envs/lzw/lib/python3.10/site-packages/requests/adapters.py", line 688, in send
    raise ConnectTimeout(e, request=request)
requests.exceptions.ConnectTimeout: HTTPSConnectionPool(host='api.wandb.ai', port=443): Max retries exceeded with url: /graphql (Caused by ConnectTimeoutError(<urllib3.connection.HTTPSConnection object at 0x7fe149107a00>, 'Connection to api.wandb.ai timed out. (connect timeout=20)'))
2024-10-21 16:40:54,441 ERROR   Thread-11 (_thread_body):1475475 [step_upload.py:_handle_event():144] Failed to upload file: /home/zwling/code/OOD-Libraries/wandb/run-20241021_155510-78bh6aux/files/requirements.txt
Traceback (most recent call last):
  File "/home/zwling/.conda/envs/lzw/lib/python3.10/site-packages/urllib3/connection.py", line 196, in _new_conn
    sock = connection.create_connection(
  File "/home/zwling/.conda/envs/lzw/lib/python3.10/site-packages/urllib3/util/connection.py", line 85, in create_connection
    raise err
  File "/home/zwling/.conda/envs/lzw/lib/python3.10/site-packages/urllib3/util/connection.py", line 73, in create_connection
    sock.connect(sa)
TimeoutError: timed out

The above exception was the direct cause of the following exception:

Traceback (most recent call last):
  File "/home/zwling/.conda/envs/lzw/lib/python3.10/site-packages/urllib3/connectionpool.py", line 789, in urlopen
    response = self._make_request(
  File "/home/zwling/.conda/envs/lzw/lib/python3.10/site-packages/urllib3/connectionpool.py", line 490, in _make_request
    raise new_e
  File "/home/zwling/.conda/envs/lzw/lib/python3.10/site-packages/urllib3/connectionpool.py", line 466, in _make_request
    self._validate_conn(conn)
  File "/home/zwling/.conda/envs/lzw/lib/python3.10/site-packages/urllib3/connectionpool.py", line 1095, in _validate_conn
    conn.connect()
  File "/home/zwling/.conda/envs/lzw/lib/python3.10/site-packages/urllib3/connection.py", line 615, in connect
    self.sock = sock = self._new_conn()
  File "/home/zwling/.conda/envs/lzw/lib/python3.10/site-packages/urllib3/connection.py", line 205, in _new_conn
    raise ConnectTimeoutError(
urllib3.exceptions.ConnectTimeoutError: (<urllib3.connection.HTTPSConnection object at 0x7fe149107a00>, 'Connection to api.wandb.ai timed out. (connect timeout=20)')

The above exception was the direct cause of the following exception:

Traceback (most recent call last):
  File "/home/zwling/.conda/envs/lzw/lib/python3.10/site-packages/requests/adapters.py", line 667, in send
    resp = conn.urlopen(
  File "/home/zwling/.conda/envs/lzw/lib/python3.10/site-packages/urllib3/connectionpool.py", line 843, in urlopen
    retries = retries.increment(
  File "/home/zwling/.conda/envs/lzw/lib/python3.10/site-packages/urllib3/util/retry.py", line 519, in increment
    raise MaxRetryError(_pool, url, reason) from reason  # type: ignore[arg-type]
urllib3.exceptions.MaxRetryError: HTTPSConnectionPool(host='api.wandb.ai', port=443): Max retries exceeded with url: /graphql (Caused by ConnectTimeoutError(<urllib3.connection.HTTPSConnection object at 0x7fe149107a00>, 'Connection to api.wandb.ai timed out. (connect timeout=20)'))

During handling of the above exception, another exception occurred:

Traceback (most recent call last):
  File "/home/zwling/.conda/envs/lzw/lib/python3.10/site-packages/wandb/sdk/lib/retry.py", line 131, in __call__
    result = self._call_fn(*args, **kwargs)
  File "/home/zwling/.conda/envs/lzw/lib/python3.10/site-packages/wandb/sdk/internal/internal_api.py", line 345, in execute
    return self.client.execute(*args, **kwargs)  # type: ignore
  File "/home/zwling/.conda/envs/lzw/lib/python3.10/site-packages/wandb/vendor/gql-0.2.0/wandb_gql/client.py", line 52, in execute
    result = self._get_result(document, *args, **kwargs)
  File "/home/zwling/.conda/envs/lzw/lib/python3.10/site-packages/wandb/vendor/gql-0.2.0/wandb_gql/client.py", line 60, in _get_result
    return self.transport.execute(document, *args, **kwargs)
  File "/home/zwling/.conda/envs/lzw/lib/python3.10/site-packages/wandb/sdk/lib/gql_request.py", line 58, in execute
    request = self.session.post(self.url, **post_args)
  File "/home/zwling/.conda/envs/lzw/lib/python3.10/site-packages/requests/sessions.py", line 637, in post
    return self.request("POST", url, data=data, json=json, **kwargs)
  File "/home/zwling/.conda/envs/lzw/lib/python3.10/site-packages/requests/sessions.py", line 589, in request
    resp = self.send(prep, **send_kwargs)
  File "/home/zwling/.conda/envs/lzw/lib/python3.10/site-packages/requests/sessions.py", line 703, in send
    r = adapter.send(request, **kwargs)
  File "/home/zwling/.conda/envs/lzw/lib/python3.10/site-packages/requests/adapters.py", line 688, in send
    raise ConnectTimeout(e, request=request)
requests.exceptions.ConnectTimeout: HTTPSConnectionPool(host='api.wandb.ai', port=443): Max retries exceeded with url: /graphql (Caused by ConnectTimeoutError(<urllib3.connection.HTTPSConnection object at 0x7fe149107a00>, 'Connection to api.wandb.ai timed out. (connect timeout=20)'))

During handling of the above exception, another exception occurred:

Traceback (most recent call last):
  File "/home/zwling/.conda/envs/lzw/lib/python3.10/site-packages/wandb/apis/normalize.py", line 41, in wrapper
    return func(*args, **kwargs)
  File "/home/zwling/.conda/envs/lzw/lib/python3.10/site-packages/wandb/sdk/internal/internal_api.py", line 2500, in upload_urls
    query_result = self.gql(
  File "/home/zwling/.conda/envs/lzw/lib/python3.10/site-packages/wandb/sdk/internal/internal_api.py", line 317, in gql
    ret = self._retry_gql(
  File "/home/zwling/.conda/envs/lzw/lib/python3.10/site-packages/wandb/sdk/lib/retry.py", line 183, in __call__
    wandb.termlog(
  File "/home/zwling/.conda/envs/lzw/lib/python3.10/site-packages/wandb/errors/term.py", line 42, in termlog
    _log(
  File "/home/zwling/.conda/envs/lzw/lib/python3.10/site-packages/wandb/errors/term.py", line 103, in _log
    click.echo(line, file=sys.stderr, nl=newline)
  File "/home/zwling/.conda/envs/lzw/lib/python3.10/site-packages/click/utils.py", line 318, in echo
    file.write(out)  # type: ignore
OSError: [Errno 5] Input/output error

During handling of the above exception, another exception occurred:

Traceback (most recent call last):
  File "/home/zwling/.conda/envs/lzw/lib/python3.10/concurrent/futures/thread.py", line 58, in run
    result = self.fn(*self.args, **self.kwargs)
  File "/home/zwling/.conda/envs/lzw/lib/python3.10/site-packages/wandb/filesync/step_upload.py", line 223, in run_and_notify
    self._do_upload(event)
  File "/home/zwling/.conda/envs/lzw/lib/python3.10/site-packages/wandb/filesync/step_upload.py", line 243, in _do_upload
    job.run()
  File "/home/zwling/.conda/envs/lzw/lib/python3.10/site-packages/wandb/filesync/upload_job.py", line 56, in run
    self.push()
  File "/home/zwling/.conda/envs/lzw/lib/python3.10/site-packages/wandb/filesync/upload_job.py", line 105, in push
    _, upload_headers, result = self._api.upload_urls(project, [self.save_name])
  File "/home/zwling/.conda/envs/lzw/lib/python3.10/site-packages/wandb/apis/normalize.py", line 87, in wrapper
    raise CommError(message, err).with_traceback(sys.exc_info()[2])
  File "/home/zwling/.conda/envs/lzw/lib/python3.10/site-packages/wandb/apis/normalize.py", line 41, in wrapper
    return func(*args, **kwargs)
  File "/home/zwling/.conda/envs/lzw/lib/python3.10/site-packages/wandb/sdk/internal/internal_api.py", line 2500, in upload_urls
    query_result = self.gql(
  File "/home/zwling/.conda/envs/lzw/lib/python3.10/site-packages/wandb/sdk/internal/internal_api.py", line 317, in gql
    ret = self._retry_gql(
  File "/home/zwling/.conda/envs/lzw/lib/python3.10/site-packages/wandb/sdk/lib/retry.py", line 183, in __call__
    wandb.termlog(
  File "/home/zwling/.conda/envs/lzw/lib/python3.10/site-packages/wandb/errors/term.py", line 42, in termlog
    _log(
  File "/home/zwling/.conda/envs/lzw/lib/python3.10/site-packages/wandb/errors/term.py", line 103, in _log
    click.echo(line, file=sys.stderr, nl=newline)
  File "/home/zwling/.conda/envs/lzw/lib/python3.10/site-packages/click/utils.py", line 318, in echo
    file.write(out)  # type: ignore
wandb.errors.CommError: [Errno 5] Input/output error
2024-10-21 16:41:06,544 INFO    wandb-upload_0:1475475 [retry.py:__call__():172] Retry attempt failed:
Traceback (most recent call last):
  File "/home/zwling/.conda/envs/lzw/lib/python3.10/site-packages/urllib3/connectionpool.py", line 536, in _make_request
    response = conn.getresponse()
  File "/home/zwling/.conda/envs/lzw/lib/python3.10/site-packages/urllib3/connection.py", line 464, in getresponse
    httplib_response = super().getresponse()
  File "/home/zwling/.conda/envs/lzw/lib/python3.10/http/client.py", line 1375, in getresponse
    response.begin()
  File "/home/zwling/.conda/envs/lzw/lib/python3.10/http/client.py", line 318, in begin
    version, status, reason = self._read_status()
  File "/home/zwling/.conda/envs/lzw/lib/python3.10/http/client.py", line 279, in _read_status
    line = str(self.fp.readline(_MAXLINE + 1), "iso-8859-1")
  File "/home/zwling/.conda/envs/lzw/lib/python3.10/socket.py", line 705, in readinto
    return self._sock.recv_into(b)
  File "/home/zwling/.conda/envs/lzw/lib/python3.10/ssl.py", line 1307, in recv_into
    return self.read(nbytes, buffer)
  File "/home/zwling/.conda/envs/lzw/lib/python3.10/ssl.py", line 1163, in read
    return self._sslobj.read(len, buffer)
TimeoutError: The read operation timed out

The above exception was the direct cause of the following exception:

Traceback (most recent call last):
  File "/home/zwling/.conda/envs/lzw/lib/python3.10/site-packages/requests/adapters.py", line 667, in send
    resp = conn.urlopen(
  File "/home/zwling/.conda/envs/lzw/lib/python3.10/site-packages/urllib3/connectionpool.py", line 843, in urlopen
    retries = retries.increment(
  File "/home/zwling/.conda/envs/lzw/lib/python3.10/site-packages/urllib3/util/retry.py", line 474, in increment
    raise reraise(type(error), error, _stacktrace)
  File "/home/zwling/.conda/envs/lzw/lib/python3.10/site-packages/urllib3/util/util.py", line 39, in reraise
    raise value
  File "/home/zwling/.conda/envs/lzw/lib/python3.10/site-packages/urllib3/connectionpool.py", line 789, in urlopen
    response = self._make_request(
  File "/home/zwling/.conda/envs/lzw/lib/python3.10/site-packages/urllib3/connectionpool.py", line 538, in _make_request
    self._raise_timeout(err=e, url=url, timeout_value=read_timeout)
  File "/home/zwling/.conda/envs/lzw/lib/python3.10/site-packages/urllib3/connectionpool.py", line 369, in _raise_timeout
    raise ReadTimeoutError(
urllib3.exceptions.ReadTimeoutError: HTTPSConnectionPool(host='api.wandb.ai', port=443): Read timed out. (read timeout=20)

During handling of the above exception, another exception occurred:

Traceback (most recent call last):
  File "/home/zwling/.conda/envs/lzw/lib/python3.10/site-packages/wandb/sdk/lib/retry.py", line 131, in __call__
    result = self._call_fn(*args, **kwargs)
  File "/home/zwling/.conda/envs/lzw/lib/python3.10/site-packages/wandb/sdk/internal/internal_api.py", line 345, in execute
    return self.client.execute(*args, **kwargs)  # type: ignore
  File "/home/zwling/.conda/envs/lzw/lib/python3.10/site-packages/wandb/vendor/gql-0.2.0/wandb_gql/client.py", line 52, in execute
    result = self._get_result(document, *args, **kwargs)
  File "/home/zwling/.conda/envs/lzw/lib/python3.10/site-packages/wandb/vendor/gql-0.2.0/wandb_gql/client.py", line 60, in _get_result
    return self.transport.execute(document, *args, **kwargs)
  File "/home/zwling/.conda/envs/lzw/lib/python3.10/site-packages/wandb/sdk/lib/gql_request.py", line 58, in execute
    request = self.session.post(self.url, **post_args)
  File "/home/zwling/.conda/envs/lzw/lib/python3.10/site-packages/requests/sessions.py", line 637, in post
    return self.request("POST", url, data=data, json=json, **kwargs)
  File "/home/zwling/.conda/envs/lzw/lib/python3.10/site-packages/requests/sessions.py", line 589, in request
    resp = self.send(prep, **send_kwargs)
  File "/home/zwling/.conda/envs/lzw/lib/python3.10/site-packages/requests/sessions.py", line 703, in send
    r = adapter.send(request, **kwargs)
  File "/home/zwling/.conda/envs/lzw/lib/python3.10/site-packages/requests/adapters.py", line 713, in send
    raise ReadTimeout(e, request=request)
requests.exceptions.ReadTimeout: HTTPSConnectionPool(host='api.wandb.ai', port=443): Read timed out. (read timeout=20)
2024-10-21 16:41:06,547 ERROR   Thread-11 (_thread_body):1475475 [step_upload.py:_handle_event():144] Failed to upload file: /tmp/tmpzx2ndrg3wandb/zcd4cguz-wandb-metadata.json
Traceback (most recent call last):
  File "/home/zwling/.conda/envs/lzw/lib/python3.10/site-packages/urllib3/connectionpool.py", line 536, in _make_request
    response = conn.getresponse()
  File "/home/zwling/.conda/envs/lzw/lib/python3.10/site-packages/urllib3/connection.py", line 464, in getresponse
    httplib_response = super().getresponse()
  File "/home/zwling/.conda/envs/lzw/lib/python3.10/http/client.py", line 1375, in getresponse
    response.begin()
  File "/home/zwling/.conda/envs/lzw/lib/python3.10/http/client.py", line 318, in begin
    version, status, reason = self._read_status()
  File "/home/zwling/.conda/envs/lzw/lib/python3.10/http/client.py", line 279, in _read_status
    line = str(self.fp.readline(_MAXLINE + 1), "iso-8859-1")
  File "/home/zwling/.conda/envs/lzw/lib/python3.10/socket.py", line 705, in readinto
    return self._sock.recv_into(b)
  File "/home/zwling/.conda/envs/lzw/lib/python3.10/ssl.py", line 1307, in recv_into
    return self.read(nbytes, buffer)
  File "/home/zwling/.conda/envs/lzw/lib/python3.10/ssl.py", line 1163, in read
    return self._sslobj.read(len, buffer)
TimeoutError: The read operation timed out

The above exception was the direct cause of the following exception:

Traceback (most recent call last):
  File "/home/zwling/.conda/envs/lzw/lib/python3.10/site-packages/requests/adapters.py", line 667, in send
    resp = conn.urlopen(
  File "/home/zwling/.conda/envs/lzw/lib/python3.10/site-packages/urllib3/connectionpool.py", line 843, in urlopen
    retries = retries.increment(
  File "/home/zwling/.conda/envs/lzw/lib/python3.10/site-packages/urllib3/util/retry.py", line 474, in increment
    raise reraise(type(error), error, _stacktrace)
  File "/home/zwling/.conda/envs/lzw/lib/python3.10/site-packages/urllib3/util/util.py", line 39, in reraise
    raise value
  File "/home/zwling/.conda/envs/lzw/lib/python3.10/site-packages/urllib3/connectionpool.py", line 789, in urlopen
    response = self._make_request(
  File "/home/zwling/.conda/envs/lzw/lib/python3.10/site-packages/urllib3/connectionpool.py", line 538, in _make_request
    self._raise_timeout(err=e, url=url, timeout_value=read_timeout)
  File "/home/zwling/.conda/envs/lzw/lib/python3.10/site-packages/urllib3/connectionpool.py", line 369, in _raise_timeout
    raise ReadTimeoutError(
urllib3.exceptions.ReadTimeoutError: HTTPSConnectionPool(host='api.wandb.ai', port=443): Read timed out. (read timeout=20)

During handling of the above exception, another exception occurred:

Traceback (most recent call last):
  File "/home/zwling/.conda/envs/lzw/lib/python3.10/site-packages/wandb/sdk/lib/retry.py", line 131, in __call__
    result = self._call_fn(*args, **kwargs)
  File "/home/zwling/.conda/envs/lzw/lib/python3.10/site-packages/wandb/sdk/internal/internal_api.py", line 345, in execute
    return self.client.execute(*args, **kwargs)  # type: ignore
  File "/home/zwling/.conda/envs/lzw/lib/python3.10/site-packages/wandb/vendor/gql-0.2.0/wandb_gql/client.py", line 52, in execute
    result = self._get_result(document, *args, **kwargs)
  File "/home/zwling/.conda/envs/lzw/lib/python3.10/site-packages/wandb/vendor/gql-0.2.0/wandb_gql/client.py", line 60, in _get_result
    return self.transport.execute(document, *args, **kwargs)
  File "/home/zwling/.conda/envs/lzw/lib/python3.10/site-packages/wandb/sdk/lib/gql_request.py", line 58, in execute
    request = self.session.post(self.url, **post_args)
  File "/home/zwling/.conda/envs/lzw/lib/python3.10/site-packages/requests/sessions.py", line 637, in post
    return self.request("POST", url, data=data, json=json, **kwargs)
  File "/home/zwling/.conda/envs/lzw/lib/python3.10/site-packages/requests/sessions.py", line 589, in request
    resp = self.send(prep, **send_kwargs)
  File "/home/zwling/.conda/envs/lzw/lib/python3.10/site-packages/requests/sessions.py", line 703, in send
    r = adapter.send(request, **kwargs)
  File "/home/zwling/.conda/envs/lzw/lib/python3.10/site-packages/requests/adapters.py", line 713, in send
    raise ReadTimeout(e, request=request)
requests.exceptions.ReadTimeout: HTTPSConnectionPool(host='api.wandb.ai', port=443): Read timed out. (read timeout=20)

During handling of the above exception, another exception occurred:

Traceback (most recent call last):
  File "/home/zwling/.conda/envs/lzw/lib/python3.10/site-packages/wandb/apis/normalize.py", line 41, in wrapper
    return func(*args, **kwargs)
  File "/home/zwling/.conda/envs/lzw/lib/python3.10/site-packages/wandb/sdk/internal/internal_api.py", line 557, in server_info_introspection
    res = self.gql(query)
  File "/home/zwling/.conda/envs/lzw/lib/python3.10/site-packages/wandb/sdk/internal/internal_api.py", line 317, in gql
    ret = self._retry_gql(
  File "/home/zwling/.conda/envs/lzw/lib/python3.10/site-packages/wandb/sdk/lib/retry.py", line 183, in __call__
    wandb.termlog(
  File "/home/zwling/.conda/envs/lzw/lib/python3.10/site-packages/wandb/errors/term.py", line 42, in termlog
    _log(
  File "/home/zwling/.conda/envs/lzw/lib/python3.10/site-packages/wandb/errors/term.py", line 103, in _log
    click.echo(line, file=sys.stderr, nl=newline)
  File "/home/zwling/.conda/envs/lzw/lib/python3.10/site-packages/click/utils.py", line 318, in echo
    file.write(out)  # type: ignore
OSError: [Errno 5] Input/output error

During handling of the above exception, another exception occurred:

Traceback (most recent call last):
  File "/home/zwling/.conda/envs/lzw/lib/python3.10/concurrent/futures/thread.py", line 58, in run
    result = self.fn(*self.args, **self.kwargs)
  File "/home/zwling/.conda/envs/lzw/lib/python3.10/site-packages/wandb/filesync/step_upload.py", line 223, in run_and_notify
    self._do_upload(event)
  File "/home/zwling/.conda/envs/lzw/lib/python3.10/site-packages/wandb/filesync/step_upload.py", line 243, in _do_upload
    job.run()
  File "/home/zwling/.conda/envs/lzw/lib/python3.10/site-packages/wandb/filesync/upload_job.py", line 56, in run
    self.push()
  File "/home/zwling/.conda/envs/lzw/lib/python3.10/site-packages/wandb/filesync/upload_job.py", line 105, in push
    _, upload_headers, result = self._api.upload_urls(project, [self.save_name])
  File "/home/zwling/.conda/envs/lzw/lib/python3.10/site-packages/wandb/apis/normalize.py", line 73, in wrapper
    raise err
  File "/home/zwling/.conda/envs/lzw/lib/python3.10/site-packages/wandb/apis/normalize.py", line 41, in wrapper
    return func(*args, **kwargs)
  File "/home/zwling/.conda/envs/lzw/lib/python3.10/site-packages/wandb/sdk/internal/internal_api.py", line 2481, in upload_urls
    has_create_run_files_mutation = self.create_run_files_introspection()
  File "/home/zwling/.conda/envs/lzw/lib/python3.10/site-packages/wandb/apis/normalize.py", line 73, in wrapper
    raise err
  File "/home/zwling/.conda/envs/lzw/lib/python3.10/site-packages/wandb/apis/normalize.py", line 41, in wrapper
    return func(*args, **kwargs)
  File "/home/zwling/.conda/envs/lzw/lib/python3.10/site-packages/wandb/sdk/internal/internal_api.py", line 2441, in create_run_files_introspection
    _, _, mutations = self.server_info_introspection()
  File "/home/zwling/.conda/envs/lzw/lib/python3.10/site-packages/wandb/apis/normalize.py", line 87, in wrapper
    raise CommError(message, err).with_traceback(sys.exc_info()[2])
  File "/home/zwling/.conda/envs/lzw/lib/python3.10/site-packages/wandb/apis/normalize.py", line 41, in wrapper
    return func(*args, **kwargs)
  File "/home/zwling/.conda/envs/lzw/lib/python3.10/site-packages/wandb/sdk/internal/internal_api.py", line 557, in server_info_introspection
    res = self.gql(query)
  File "/home/zwling/.conda/envs/lzw/lib/python3.10/site-packages/wandb/sdk/internal/internal_api.py", line 317, in gql
    ret = self._retry_gql(
  File "/home/zwling/.conda/envs/lzw/lib/python3.10/site-packages/wandb/sdk/lib/retry.py", line 183, in __call__
    wandb.termlog(
  File "/home/zwling/.conda/envs/lzw/lib/python3.10/site-packages/wandb/errors/term.py", line 42, in termlog
    _log(
  File "/home/zwling/.conda/envs/lzw/lib/python3.10/site-packages/wandb/errors/term.py", line 103, in _log
    click.echo(line, file=sys.stderr, nl=newline)
  File "/home/zwling/.conda/envs/lzw/lib/python3.10/site-packages/click/utils.py", line 318, in echo
    file.write(out)  # type: ignore
wandb.errors.CommError: [Errno 5] Input/output error
2024-10-21 16:41:07,174 INFO    SenderThread:1475475 [file_stream.py:finish():601] file stream finish called
2024-10-21 16:43:19,855 WARNING FileStreamThread:1475475 [file_stream.py:request_with_retry():674] requests_with_retry encountered retryable exception: ('Connection aborted.', RemoteDisconnected('Remote end closed connection without response')). func: <bound method Session.post of <requests.sessions.Session object at 0x7fe139738ac0>>, args: ('https://api.wandb.ai/files/zwling/ood-record/78bh6aux/file_stream',), kwargs: {'json': {'complete': False, 'failed': False, 'dropped': 0, 'uploaded': []}}
2024-10-21 16:51:32,811 WARNING FileStreamThread:1475475 [file_stream.py:request_with_retry():674] requests_with_retry encountered retryable exception: ('Connection aborted.', RemoteDisconnected('Remote end closed connection without response')). func: <bound method Session.post of <requests.sessions.Session object at 0x7fe139738ac0>>, args: ('https://api.wandb.ai/files/zwling/ood-record/78bh6aux/file_stream',), kwargs: {'json': {'complete': False, 'failed': False, 'dropped': 0, 'uploaded': []}}
2024-10-21 16:51:35,935 INFO    SenderThread:1475475 [file_stream.py:finish():605] file stream finish is done
