2024-10-21 16:05:37,865 INFO    StreamThr :1481279 [internal.py:wandb_internal():85] W&B internal server running at pid: 1481279, started at: 2024-10-21 16:05:37.864953
2024-10-21 16:05:37,868 DEBUG   HandlerThread:1481279 [handler.py:handle_request():158] handle_request: status
2024-10-21 16:05:37,870 INFO    WriterThread:1481279 [datastore.py:open_for_write():87] open: /home/zwling/code/OOD-Libraries/wandb/run-20241021_160537-chnm5oby/run-chnm5oby.wandb
2024-10-21 16:05:37,872 DEBUG   SenderThread:1481279 [sender.py:send():391] send: header
2024-10-21 16:05:37,873 DEBUG   SenderThread:1481279 [sender.py:send():391] send: run
2024-10-21 16:05:42,874 DEBUG   HandlerThread:1481279 [handler.py:handle_request():158] handle_request: keepalive
2024-10-21 16:05:47,876 DEBUG   HandlerThread:1481279 [handler.py:handle_request():158] handle_request: keepalive
2024-10-21 16:05:52,877 DEBUG   HandlerThread:1481279 [handler.py:handle_request():158] handle_request: keepalive
2024-10-21 16:05:57,879 DEBUG   HandlerThread:1481279 [handler.py:handle_request():158] handle_request: keepalive
2024-10-21 16:06:02,881 DEBUG   HandlerThread:1481279 [handler.py:handle_request():158] handle_request: keepalive
2024-10-21 16:06:07,882 DEBUG   HandlerThread:1481279 [handler.py:handle_request():158] handle_request: keepalive
2024-10-21 16:06:12,884 DEBUG   HandlerThread:1481279 [handler.py:handle_request():158] handle_request: keepalive
2024-10-21 16:06:17,885 DEBUG   HandlerThread:1481279 [handler.py:handle_request():158] handle_request: keepalive
2024-10-21 16:06:22,887 DEBUG   HandlerThread:1481279 [handler.py:handle_request():158] handle_request: keepalive
2024-10-21 16:06:27,888 DEBUG   HandlerThread:1481279 [handler.py:handle_request():158] handle_request: keepalive
2024-10-21 16:06:32,890 DEBUG   HandlerThread:1481279 [handler.py:handle_request():158] handle_request: keepalive
2024-10-21 16:06:37,892 DEBUG   HandlerThread:1481279 [handler.py:handle_request():158] handle_request: keepalive
2024-10-21 16:06:41,381 INFO    SenderThread:1481279 [retry.py:__call__():172] Retry attempt failed:
Traceback (most recent call last):
  File "/home/zwling/.conda/envs/lzw/lib/python3.10/site-packages/urllib3/connection.py", line 196, in _new_conn
    sock = connection.create_connection(
  File "/home/zwling/.conda/envs/lzw/lib/python3.10/site-packages/urllib3/util/connection.py", line 85, in create_connection
    raise err
  File "/home/zwling/.conda/envs/lzw/lib/python3.10/site-packages/urllib3/util/connection.py", line 73, in create_connection
    sock.connect(sa)
TimeoutError: timed out

The above exception was the direct cause of the following exception:

Traceback (most recent call last):
  File "/home/zwling/.conda/envs/lzw/lib/python3.10/site-packages/urllib3/connectionpool.py", line 789, in urlopen
    response = self._make_request(
  File "/home/zwling/.conda/envs/lzw/lib/python3.10/site-packages/urllib3/connectionpool.py", line 490, in _make_request
    raise new_e
  File "/home/zwling/.conda/envs/lzw/lib/python3.10/site-packages/urllib3/connectionpool.py", line 466, in _make_request
    self._validate_conn(conn)
  File "/home/zwling/.conda/envs/lzw/lib/python3.10/site-packages/urllib3/connectionpool.py", line 1095, in _validate_conn
    conn.connect()
  File "/home/zwling/.conda/envs/lzw/lib/python3.10/site-packages/urllib3/connection.py", line 615, in connect
    self.sock = sock = self._new_conn()
  File "/home/zwling/.conda/envs/lzw/lib/python3.10/site-packages/urllib3/connection.py", line 205, in _new_conn
    raise ConnectTimeoutError(
urllib3.exceptions.ConnectTimeoutError: (<urllib3.connection.HTTPSConnection object at 0x7ffb08762e00>, 'Connection to api.wandb.ai timed out. (connect timeout=20)')

The above exception was the direct cause of the following exception:

Traceback (most recent call last):
  File "/home/zwling/.conda/envs/lzw/lib/python3.10/site-packages/requests/adapters.py", line 667, in send
    resp = conn.urlopen(
  File "/home/zwling/.conda/envs/lzw/lib/python3.10/site-packages/urllib3/connectionpool.py", line 843, in urlopen
    retries = retries.increment(
  File "/home/zwling/.conda/envs/lzw/lib/python3.10/site-packages/urllib3/util/retry.py", line 519, in increment
    raise MaxRetryError(_pool, url, reason) from reason  # type: ignore[arg-type]
urllib3.exceptions.MaxRetryError: HTTPSConnectionPool(host='api.wandb.ai', port=443): Max retries exceeded with url: /graphql (Caused by ConnectTimeoutError(<urllib3.connection.HTTPSConnection object at 0x7ffb08762e00>, 'Connection to api.wandb.ai timed out. (connect timeout=20)'))

During handling of the above exception, another exception occurred:

Traceback (most recent call last):
  File "/home/zwling/.conda/envs/lzw/lib/python3.10/site-packages/wandb/sdk/lib/retry.py", line 131, in __call__
    result = self._call_fn(*args, **kwargs)
  File "/home/zwling/.conda/envs/lzw/lib/python3.10/site-packages/wandb/sdk/internal/internal_api.py", line 345, in execute
    return self.client.execute(*args, **kwargs)  # type: ignore
  File "/home/zwling/.conda/envs/lzw/lib/python3.10/site-packages/wandb/vendor/gql-0.2.0/wandb_gql/client.py", line 52, in execute
    result = self._get_result(document, *args, **kwargs)
  File "/home/zwling/.conda/envs/lzw/lib/python3.10/site-packages/wandb/vendor/gql-0.2.0/wandb_gql/client.py", line 60, in _get_result
    return self.transport.execute(document, *args, **kwargs)
  File "/home/zwling/.conda/envs/lzw/lib/python3.10/site-packages/wandb/sdk/lib/gql_request.py", line 58, in execute
    request = self.session.post(self.url, **post_args)
  File "/home/zwling/.conda/envs/lzw/lib/python3.10/site-packages/requests/sessions.py", line 637, in post
    return self.request("POST", url, data=data, json=json, **kwargs)
  File "/home/zwling/.conda/envs/lzw/lib/python3.10/site-packages/requests/sessions.py", line 589, in request
    resp = self.send(prep, **send_kwargs)
  File "/home/zwling/.conda/envs/lzw/lib/python3.10/site-packages/requests/sessions.py", line 703, in send
    r = adapter.send(request, **kwargs)
  File "/home/zwling/.conda/envs/lzw/lib/python3.10/site-packages/requests/adapters.py", line 688, in send
    raise ConnectTimeout(e, request=request)
requests.exceptions.ConnectTimeout: HTTPSConnectionPool(host='api.wandb.ai', port=443): Max retries exceeded with url: /graphql (Caused by ConnectTimeoutError(<urllib3.connection.HTTPSConnection object at 0x7ffb08762e00>, 'Connection to api.wandb.ai timed out. (connect timeout=20)'))
2024-10-21 16:06:42,894 DEBUG   HandlerThread:1481279 [handler.py:handle_request():158] handle_request: keepalive
2024-10-21 16:06:47,896 DEBUG   HandlerThread:1481279 [handler.py:handle_request():158] handle_request: keepalive
2024-10-21 16:06:52,898 DEBUG   HandlerThread:1481279 [handler.py:handle_request():158] handle_request: keepalive
2024-10-21 16:06:57,901 DEBUG   HandlerThread:1481279 [handler.py:handle_request():158] handle_request: keepalive
2024-10-21 16:06:59,209 DEBUG   HandlerThread:1481279 [handler.py:handle_request():158] handle_request: shutdown
2024-10-21 16:06:59,209 INFO    HandlerThread:1481279 [handler.py:finish():884] shutting down handler
2024-10-21 16:06:59,891 INFO    WriterThread:1481279 [datastore.py:close():296] close: /home/zwling/code/OOD-Libraries/wandb/run-20241021_160537-chnm5oby/run-chnm5oby.wandb
2024-10-21 16:59:09,181 INFO    SenderThread:1481279 [dir_watcher.py:__init__():211] watching files in: /home/zwling/code/OOD-Libraries/wandb/run-20241021_160537-chnm5oby/files
2024-10-21 16:59:09,181 INFO    SenderThread:1481279 [sender.py:_start_run_threads():1200] run started: chnm5oby with start time 1729497937.864435
2024-10-21 16:59:09,181 INFO    SenderThread:1481279 [sender.py:finish():1631] shutting down sender
2024-10-21 16:59:09,181 INFO    SenderThread:1481279 [dir_watcher.py:finish():358] shutting down directory watcher
2024-10-21 16:59:10,181 INFO    SenderThread:1481279 [dir_watcher.py:finish():388] scan: /home/zwling/code/OOD-Libraries/wandb/run-20241021_160537-chnm5oby/files
2024-10-21 16:59:10,181 INFO    SenderThread:1481279 [dir_watcher.py:finish():402] scan save: /home/zwling/code/OOD-Libraries/wandb/run-20241021_160537-chnm5oby/files/config.yaml config.yaml
2024-10-21 16:59:10,181 INFO    SenderThread:1481279 [file_pusher.py:finish():169] shutting down file pusher
2024-10-21 16:59:10,182 INFO    SenderThread:1481279 [file_pusher.py:join():175] waiting for file pusher
2024-10-21 16:59:11,079 INFO    wandb-upload_0:1481279 [upload_job.py:push():130] Uploaded file /home/zwling/code/OOD-Libraries/wandb/run-20241021_160537-chnm5oby/files/config.yaml
2024-10-21 16:59:11,684 INFO    SenderThread:1481279 [file_stream.py:finish():601] file stream finish called
2024-10-21 17:01:22,464 WARNING FileStreamThread:1481279 [file_stream.py:request_with_retry():674] requests_with_retry encountered retryable exception: HTTPSConnectionPool(host='api.wandb.ai', port=443): Max retries exceeded with url: /files/zwling/ood-record/chnm5oby/file_stream (Caused by ConnectTimeoutError(<urllib3.connection.HTTPSConnection object at 0x7ffb0448e410>, 'Connection to api.wandb.ai timed out. (connect timeout=None)')). func: <bound method Session.post of <requests.sessions.Session object at 0x7ffb087638e0>>, args: ('https://api.wandb.ai/files/zwling/ood-record/chnm5oby/file_stream',), kwargs: {'json': {'complete': True, 'exitcode': 0, 'dropped': 0, 'uploaded': ['config.yaml']}}
2024-10-21 17:06:48,269 WARNING FileStreamThread:1481279 [file_stream.py:request_with_retry():674] requests_with_retry encountered retryable exception: ('Connection aborted.', RemoteDisconnected('Remote end closed connection without response')). func: <bound method Session.post of <requests.sessions.Session object at 0x7ffb087638e0>>, args: ('https://api.wandb.ai/files/zwling/ood-record/chnm5oby/file_stream',), kwargs: {'json': {'complete': True, 'exitcode': 0, 'dropped': 0, 'uploaded': ['config.yaml']}}
2024-10-21 17:06:53,621 INFO    SenderThread:1481279 [file_stream.py:finish():605] file stream finish is done
