2024-10-21 16:05:37,860 INFO    MainThread:1481243 [wandb_setup.py:_flush():77] Current SDK version is 0.17.8
2024-10-21 16:05:37,861 INFO    MainThread:1481243 [wandb_setup.py:_flush():77] Configure stats pid to 1481243
2024-10-21 16:05:37,861 INFO    MainThread:1481243 [wandb_setup.py:_flush():77] Loading settings from /home/zwling/.config/wandb/settings
2024-10-21 16:05:37,861 INFO    MainThread:1481243 [wandb_setup.py:_flush():77] Loading settings from /home/zwling/code/OOD-Libraries/wandb/settings
2024-10-21 16:05:37,861 INFO    MainThread:1481243 [wandb_setup.py:_flush():77] Loading settings from environment variables: {}
2024-10-21 16:05:37,861 INFO    MainThread:1481243 [wandb_setup.py:_flush():77] Applying setup settings: {'_disable_service': False}
2024-10-21 16:05:37,861 INFO    MainThread:1481243 [wandb_setup.py:_flush():77] Inferring run settings from compute environment: {'program_relpath': 'ood_eval.py', 'program_abspath': '/home/zwling/code/OOD-Libraries/ood_eval.py', 'program': '/home/zwling/code/OOD-Libraries/ood_eval.py'}
2024-10-21 16:05:37,861 INFO    MainThread:1481243 [wandb_setup.py:_flush():77] Applying login settings: {}
2024-10-21 16:05:37,861 INFO    MainThread:1481243 [wandb_init.py:_log_setup():524] Logging user logs to /home/zwling/code/OOD-Libraries/wandb/run-20241021_160537-chnm5oby/logs/debug.log
2024-10-21 16:05:37,861 INFO    MainThread:1481243 [wandb_init.py:_log_setup():525] Logging internal logs to /home/zwling/code/OOD-Libraries/wandb/run-20241021_160537-chnm5oby/logs/debug-internal.log
2024-10-21 16:05:37,861 INFO    MainThread:1481243 [wandb_init.py:init():607] calling init triggers
2024-10-21 16:05:37,861 INFO    MainThread:1481243 [wandb_init.py:init():614] wandb.init called with sweep_config: {}
config: {'architecture': 'VIT', 'ind_dataset': 'ImageNet', 'ood_dataset': 'ImageNet_O', 'method': 'GEN'}
2024-10-21 16:05:37,861 INFO    MainThread:1481243 [wandb_init.py:init():657] starting backend
2024-10-21 16:05:37,861 INFO    MainThread:1481243 [wandb_init.py:init():661] setting up manager
2024-10-21 16:05:37,862 INFO    MainThread:1481243 [backend.py:_multiprocessing_setup():105] multiprocessing start_methods=fork,spawn,forkserver, using: spawn
2024-10-21 16:05:37,864 INFO    MainThread:1481243 [wandb_init.py:init():669] backend started and connected
2024-10-21 16:05:37,865 INFO    MainThread:1481243 [wandb_init.py:init():767] updated telemetry
2024-10-21 16:05:37,871 INFO    MainThread:1481243 [wandb_init.py:init():800] communicating run to backend with 90.0 second timeout
2024-10-21 16:06:44,136 INFO    Thread-1 (wrapped_target):1481243 [retry.py:__call__():172] Retry attempt failed:
Traceback (most recent call last):
  File "/home/zwling/.conda/envs/lzw/lib/python3.10/site-packages/urllib3/connection.py", line 196, in _new_conn
    sock = connection.create_connection(
  File "/home/zwling/.conda/envs/lzw/lib/python3.10/site-packages/urllib3/util/connection.py", line 85, in create_connection
    raise err
  File "/home/zwling/.conda/envs/lzw/lib/python3.10/site-packages/urllib3/util/connection.py", line 73, in create_connection
    sock.connect(sa)
TimeoutError: timed out

The above exception was the direct cause of the following exception:

Traceback (most recent call last):
  File "/home/zwling/.conda/envs/lzw/lib/python3.10/site-packages/urllib3/connectionpool.py", line 789, in urlopen
    response = self._make_request(
  File "/home/zwling/.conda/envs/lzw/lib/python3.10/site-packages/urllib3/connectionpool.py", line 490, in _make_request
    raise new_e
  File "/home/zwling/.conda/envs/lzw/lib/python3.10/site-packages/urllib3/connectionpool.py", line 466, in _make_request
    self._validate_conn(conn)
  File "/home/zwling/.conda/envs/lzw/lib/python3.10/site-packages/urllib3/connectionpool.py", line 1095, in _validate_conn
    conn.connect()
  File "/home/zwling/.conda/envs/lzw/lib/python3.10/site-packages/urllib3/connection.py", line 615, in connect
    self.sock = sock = self._new_conn()
  File "/home/zwling/.conda/envs/lzw/lib/python3.10/site-packages/urllib3/connection.py", line 205, in _new_conn
    raise ConnectTimeoutError(
urllib3.exceptions.ConnectTimeoutError: (<urllib3.connection.HTTPSConnection object at 0x7f0374b8ecb0>, 'Connection to api.wandb.ai timed out. (connect timeout=20)')

The above exception was the direct cause of the following exception:

Traceback (most recent call last):
  File "/home/zwling/.conda/envs/lzw/lib/python3.10/site-packages/requests/adapters.py", line 667, in send
    resp = conn.urlopen(
  File "/home/zwling/.conda/envs/lzw/lib/python3.10/site-packages/urllib3/connectionpool.py", line 843, in urlopen
    retries = retries.increment(
  File "/home/zwling/.conda/envs/lzw/lib/python3.10/site-packages/urllib3/util/retry.py", line 519, in increment
    raise MaxRetryError(_pool, url, reason) from reason  # type: ignore[arg-type]
urllib3.exceptions.MaxRetryError: HTTPSConnectionPool(host='api.wandb.ai', port=443): Max retries exceeded with url: /graphql (Caused by ConnectTimeoutError(<urllib3.connection.HTTPSConnection object at 0x7f0374b8ecb0>, 'Connection to api.wandb.ai timed out. (connect timeout=20)'))

During handling of the above exception, another exception occurred:

Traceback (most recent call last):
  File "/home/zwling/.conda/envs/lzw/lib/python3.10/site-packages/wandb/sdk/lib/retry.py", line 131, in __call__
    result = self._call_fn(*args, **kwargs)
  File "/home/zwling/.conda/envs/lzw/lib/python3.10/site-packages/wandb/sdk/internal/internal_api.py", line 345, in execute
    return self.client.execute(*args, **kwargs)  # type: ignore
  File "/home/zwling/.conda/envs/lzw/lib/python3.10/site-packages/wandb/vendor/gql-0.2.0/wandb_gql/client.py", line 52, in execute
    result = self._get_result(document, *args, **kwargs)
  File "/home/zwling/.conda/envs/lzw/lib/python3.10/site-packages/wandb/vendor/gql-0.2.0/wandb_gql/client.py", line 60, in _get_result
    return self.transport.execute(document, *args, **kwargs)
  File "/home/zwling/.conda/envs/lzw/lib/python3.10/site-packages/wandb/sdk/lib/gql_request.py", line 58, in execute
    request = self.session.post(self.url, **post_args)
  File "/home/zwling/.conda/envs/lzw/lib/python3.10/site-packages/requests/sessions.py", line 637, in post
    return self.request("POST", url, data=data, json=json, **kwargs)
  File "/home/zwling/.conda/envs/lzw/lib/python3.10/site-packages/requests/sessions.py", line 589, in request
    resp = self.send(prep, **send_kwargs)
  File "/home/zwling/.conda/envs/lzw/lib/python3.10/site-packages/requests/sessions.py", line 703, in send
    r = adapter.send(request, **kwargs)
  File "/home/zwling/.conda/envs/lzw/lib/python3.10/site-packages/requests/adapters.py", line 688, in send
    raise ConnectTimeout(e, request=request)
requests.exceptions.ConnectTimeout: HTTPSConnectionPool(host='api.wandb.ai', port=443): Max retries exceeded with url: /graphql (Caused by ConnectTimeoutError(<urllib3.connection.HTTPSConnection object at 0x7f0374b8ecb0>, 'Connection to api.wandb.ai timed out. (connect timeout=20)'))
2024-10-21 16:06:59,197 WARNING MainThread:1481243 [wandb_init.py:init():1232] interrupted
Traceback (most recent call last):
  File "/home/zwling/.conda/envs/lzw/lib/python3.10/site-packages/wandb/sdk/wandb_init.py", line 1228, in init
    return wi.init()
  File "/home/zwling/.conda/envs/lzw/lib/python3.10/site-packages/wandb/sdk/wandb_init.py", line 803, in init
    result = run_init_handle.wait(
  File "/home/zwling/.conda/envs/lzw/lib/python3.10/site-packages/wandb/sdk/lib/mailbox.py", line 283, in wait
    found, abandoned = self._slot._get_and_clear(timeout=wait_timeout)
  File "/home/zwling/.conda/envs/lzw/lib/python3.10/site-packages/wandb/sdk/lib/mailbox.py", line 130, in _get_and_clear
    if self._wait(timeout=timeout):
  File "/home/zwling/.conda/envs/lzw/lib/python3.10/site-packages/wandb/sdk/lib/mailbox.py", line 126, in _wait
    return self._event.wait(timeout=timeout)
  File "/home/zwling/.conda/envs/lzw/lib/python3.10/threading.py", line 607, in wait
    signaled = self._cond.wait(timeout)
  File "/home/zwling/.conda/envs/lzw/lib/python3.10/threading.py", line 324, in wait
    gotit = waiter.acquire(True, timeout)
KeyboardInterrupt
